Workbook

Sheet Speed
A1: Speed (All) | B1: Time Headway | C1: Speed (Cars) | D1: Speed (Bikes) | E1: Speed (CNGs) | F1: Speed (2W+3Ws)
A2: {=_xlfn.LET(_xlpm.data, _xlfn.VSTACK('3.35:17.21'!G3:G32,'3.35:17.21'!G35:G65),_xlfn._xlws.FILTER(_xlpm.data, (_xlpm.data<>0)*(_xlpm.data<>"")))} -> 23.9 | B2: {=_xlfn.LET(_xlpm.data, _xlfn.VSTACK('3.35:17.21'!D3:D32,'3.35:17.21'!D35:D65),_xlfn._xlws.FILTER(_xlpm.data, (_xlpm.data<>0)*(_xlpm.data<>"")))} -> 0.4 | C2: {=_xlfn.LET(_xlpm.data, _xlfn.VSTACK('3.35:17.21'!G3:G32,'3.35:17.21'!G35:G65), _xlpm.type, _xlfn.VSTACK('3.35:17.21'!B3:B32,'3.35:17.21'!B35:B65), _xlfn._xlws.FILTER(_xlpm.data,(_xlpm.data<>0)*(_xlpm.data<>"")*((_xlpm.type="Car"))))} -> 26.9 | D2: {=_xlfn.LET(_xlpm.data, _xlfn.VSTACK('3.35:17.21'!G3:G32,'3.35:17.21'!G35:G65), _xlpm.type, _xlfn.VSTACK('3.35:17.21'!B3:B32,'3.35:17.21'!B35:B65), _xlfn._xlws.FILTER(_xlpm.data,(_xlpm.data<>0)*(_xlpm.data<>"")*((_xlpm.type="Motorbike"))))} -> 23.9 | E2: {=_xlfn.LET(_xlpm.data, _xlfn.VSTACK('3.35:17.21'!G3:G32,'3.35:17.21'!G35:G65), _xlpm.type, _xlfn.VSTACK('3.35:17.21'!B3:B32,'3.35:17.21'!B35:B65), _xlfn._xlws.FILTER(_xlpm.data,(_xlpm.data<>0)*(_xlpm.data<>"")*((_xlpm.type="CNG"))))} -> 17.6 | F2: {=_xlfn.LET(_xlpm.data, _xlfn.VSTACK('3.35:17.21'!G3:G32,'3.35:17.21'!G35:G65), _xlpm.type, _xlfn.VSTACK('3.35:17.21'!B3:B32,'3.35:17.21'!B35:B65), _xlfn._xlws.FILTER(_xlpm.data,(_xlpm.data<>0)*(_xlpm.data<>"")*((_xlpm.type="CNG")+(_xlpm.type="Motorbike"))))} -> 23.9
A3: 21.1 | B3: 1.04 | C3: 19 | D3: 21.1 | E3: 20 | F3: 21.1
A4: 26.9 | B4: 1.16 | C4: 16.6 | D4: 17.9 | E4: 16.6 | F4: 17.9
A5: 17.9 | B5: 1.24 | C5: 17.6 | D5: 15 | E5: 14.3 | F5: 17.6
A6: 19 | B6: 2.16 | C6: 21.8 | D6: 21.7 | E6: 21.8 | F6: 20 | Y6: Speed (km/h) | Z6: Cumulative frequency | AA6: Cumulative percentage
A7: 16.6 | B7: 2.64 | C7: 20.5 | D7: 30 | E7: 17.1 | F7: 16.6
A8: 17.6 | B8: 2.2 | C8: 24 | D8: 21.7 | E8: 23.9 | F8: 15 | Y8: 0 | Z8: =COUNTIF(_xlfn.ANCHORARRAY($A$2),"<="&Y8) -> 0 | AA8: =Z8/$Z$15 -> 0
A9: 16.2 | B9: 2.68 | C9: 19.8 | D9: 26.1 | E9: 19 | F9: 14.3 | Y9: 5 | Z9: =COUNTIF(_xlfn.ANCHORARRAY($A$2),"<="&Y9) -> 2 | AA9: =Z9/$Z$15 -> 0.0041407867
A10: 21.8 | B10: 1.48 | C10: 33 | D10: 26.6 | E10: 18.1 | F10: 21.7 | Y10: 10 | Z10: =COUNTIF(_xlfn.ANCHORARRAY($A$2),"<="&Y10) -> 10 | AA10: =Z10/$Z$15 -> 0.020703934
A11: 17.6 | B11: 1.64 | C11: 17.4 | D11: 19.4 | E11: 16.8 | F11: 30 | Y11: 15 | Z11: =COUNTIF(_xlfn.ANCHORARRAY($A$2),"<="&Y11) -> 51 | AA11: =Z11/$Z$15 -> 0.10559006
A12: 20.5 | B12: 1.68 | C12: 15.5 | D12: 31 | E12: 21.4 | F12: 21.8 | Y12: 20 | Z12: =COUNTIF(_xlfn.ANCHORARRAY($A$2),"<="&Y12) -> 224 | AA12: =Z12/$Z$15 -> 0.46376812
A13: 24 | B13: 1.68 | C13: 11.9 | D13: 33.7 | E13: 17.3 | F13: 21.7 | Y13: 25 | Z13: =COUNTIF(_xlfn.ANCHORARRAY($A$2),"<="&Y13) -> 408 | AA13: =Z13/$Z$15 -> 0.8447205
A14: 20 | B14: 1 | C14: 17.5 | D14: 33.9 | E14: 24.3 | F14: 26.1 | Y14: 30 | Z14: =COUNTIF(_xlfn.ANCHORARRAY($A$2),"<="&Y14) -> 465 | AA14: =Z14/$Z$15 -> 0.96273292
A15: 19.8 | B15: 3.44 | C15: 17.2 | D15: 21.1 | E15: 21.4 | F15: 17.1 | Y15: 35 | Z15: =COUNTIF(_xlfn.ANCHORARRAY($A$2),"<="&Y15) -> 483 | AA15: =Z15/$Z$15 -> 1
A16: 16.6 | B16: 1.2 | C16: 15.1 | D16: 14.4 | E16: 22.1 | F16: 26.6
A17: 33 | B17: 2.68 | C17: 28.8 | D17: 18.1 | E17: 23.4 | F17: 23.9
A18: 17.4 | B18: 1.6 | C18: 18 | D18: 19.1 | E18: 19.8 | F18: 19.4
A19: 15.5 | B19: 1.6 | C19: 17 | D19: 20.1 | E19: 22.6 | F19: 19
A20: 11.9 | B20: 1.2 | C20: 14.2 | D20: 23.5 | E20: 16.9 | F20: 31
A21: 17.5 | B21: 0.8 | C21: 18.7 | D21: 16.6 | E21: 18.1 | F21: 33.7
A22: 17.2 | B22: 1.48 | C22: 14.9 | D22: 15.7 | E22: 16.8 | F22: 33.9
A23: 15.1 | B23: 0.8 | C23: 21.6 | D23: 25 | E23: 14.7 | F23: 18.1
A24: 15 | B24: 1.24 | C24: 19.5 | D24: 19.2 | E24: 23.5 | F24: 16.8
A25: 28.8 | B25: 1.36 | C25: 20 | D25: 24.6 | E25: 15.5 | F25: 21.1
A26: 18 | B26: 1.6 | C26: 19.5 | D26: 27.7 | E26: 17.9 | F26: 21.4
A27: 17 | B27: 0.04 | C27: 18.2 | D27: 19.1 | E27: 23.6 | F27: 14.4
A28: 14.2 | B28: 2.08 | C28: 12.6 | D28: 17.5 | E28: 23 | F28: 18.1
A29: 18.7 | B29: 2.88 | C29: 22.6 | D29: 19 | E29: 17.2 | F29: 19.1 | V29: Speed | W29: Cumulative frequency | X29: Cumulative percentage
A30: 14.9 | B30: 4.32 | C30: 25.2 | D30: 22 | E30: 14.3 | F30: 17.3
A31: 21.6 | B31: 0.08 | C31: 25 | D31: 24.7 | E31: 19.3 | F31: 20.1 | V31: 0 | W31: =COUNTIF(_xlfn.ANCHORARRAY($C$2),"<="&V31) -> 0 | X31: =W31/$W$38 -> 0
A32: 19.5 | B32: 1.24 | C32: 23.1 | D32: 25.8 | E32: 19.4 | F32: 24.3 | V32: 5 | W32: =COUNTIF(_xlfn.ANCHORARRAY($C$2),"<="&V32) -> 1 | X32: =W32/$W$38 -> 0.0036764706
A33: 14.3 | B33: 0.96 | C33: 21.5 | D33: 16.9 | E33: 21.1 | F33: 23.5 | V33: 10 | W33: =COUNTIF(_xlfn.ANCHORARRAY($C$2),"<="&V33) -> 4 | X33: =W33/$W$38 -> 0.014705882
A34: 21.7 | B34: 1.8 | C34: 11.7 | D34: 24.3 | E34: 21.200001 | F34: 21.4 | V34: 15 | W34: =COUNTIF(_xlfn.ANCHORARRAY($C$2),"<="&V34) -> 31 | X34: =W34/$W$38 -> 0.11397059
A35: 20 | B35: 7.64 | C35: 24.3 | D35: 20.3 | E35: 20.6 | F35: 16.6 | V35: 20 | W35: =COUNTIF(_xlfn.ANCHORARRAY($C$2),"<="&V35) -> 129 | X35: =W35/$W$38 -> 0.47426471
A36: 19.5 | B36: 4.2 | C36: 21.3 | D36: 16.9 | E36: 22.9 | F36: 15.7 | V36: 25 | W36: =COUNTIF(_xlfn.ANCHORARRAY($C$2),"<="&V36) -> 232 | X36: =W36/$W$38 -> 0.85294118
A37: 18.2 | B37: 1.28 | C37: 23.5 | D37: 21.4 | E37: 18.799999 | F37: 25 | V37: 30 | W37: =COUNTIF(_xlfn.ANCHORARRAY($C$2),"<="&V37) -> 265 | X37: =W37/$W$38 -> 0.97426471
A38: 12.6 | B38: 2 | C38: 22.1 | D38: 27.9 | E38: 16.9 | F38: 22.1 | V38: 35 | W38: =COUNTIF(_xlfn.ANCHORARRAY($C$2),"<="&V38) -> 272 | X38: =W38/$W$38 -> 1
A39: 22.6 | B39: 1.64 | C39: 22.2 | D39: 16.799999 | E39: 24.200001 | F39: 23.4 | V39: 50% = 20km/h
A40: 25.2 | B40: 2.28 | C40: 20.4 | D40: 33.599998 | E40: 18.200001 | F40: 19.2
...

Sheet Cars L2+3
A1: Time | B1: ID | C1: Vehicle | D1: Headway | E1: Gap | F1: Gap (deduced) | G1: Speed | H1: Gap/ Speed(kmph) | I1: Gap/ Speed(mps) | J1: Min spacing | K1: Speed diff
A2: 3.35 | B2: - | C2: - | D2: 0 | E2: 0 | F2: 0 | G2: - | H2: 0 | I2: 0 | J2: 0 | L2: Headway | M2: Gap (m)
B3: 12 | C3: Car | D3: 2.16 | E3: 9.4 | F3: 9.96 | G3: 16.6 | H3: =E3/G3 -> 0.56626506 | I3: =E3/(G3/3.6) -> 2.0385542 | J3: 1.522331 | L3: 0 | M3: 0
B4: 52 | C4: Car | D4: 2.64 | E4: 10.42 | F4: 12.906667 | G4: 17.6 | H4: =E4/G4 -> 0.59204545 | I4: =E4/(G4/3.6) -> 2.1313636 | J4: 1.6651866 | L4: 0.2 | M4: =SLOPE($E$3:$E$117, $D$3:$D$117) * L4 + INTERCEPT($E$3:$E$117, $D$3:$D$117) -> 1.9736573
B5: 120 | C5: Car | D5: 1.68 | E5: 8.88 | F5: 11.2 | G5: 24 | H5: =E5/G5 -> 0.37 | I5: =E5/(G5/3.6) -> 1.332 | J5: 1.3082723 | L5: 0.4 | M5: =SLOPE($E$3:$E$120, $D$3:$D$120) * L5 + INTERCEPT($E$3:$E$120, $D$3:$D$120) -> 2.9232048
B6: 189 | C6: Car | D6: 2.68 | E6: 11.16 | F6: 12.953333 | G6: 17.4 | H6: =E6/G6 -> 0.64137931 | I6: =E6/(G6/3.6) -> 2.3089655 | J6: 1.7881768 | L6: 0.6 | M6: =SLOPE($E$3:$E$120, $D$3:$D$120) * L6 + INTERCEPT($E$3:$E$120, $D$3:$D$120) -> 3.8727522
B7: 177 | C7: Car | D7: 1.6 | E7: 7.12 | F7: 6.8888889 | G7: 15.5 | H7: =E7/G7 -> 0.45935484 | I7: =E7/(G7/3.6) -> 1.6536774 | J7: 1.1703512 | L7: 0.8 | M7: =SLOPE($E$3:$E$120, $D$3:$D$120) * L7 + INTERCEPT($E$3:$E$120, $D$3:$D$120) -> 4.8222997
B8: 197 | C8: Car | D8: 1.6 | E8: 5.01 | F8: 5.2888889 | G8: 11.9 | H8: =E8/G8 -> 0.4210084 | I8: =E8/(G8/3.6) -> 1.5156303 | J8: 0.86595691 | L8: 1 | M8: =SLOPE($E$3:$E$120, $D$3:$D$120) * L8 + INTERCEPT($E$3:$E$120, $D$3:$D$120) -> 5.7718471
B9: 203 | C9: Car | D9: 1.2 | E9: 4.9 | F9: 5.8333333 | G9: 17.5 | H9: =E9/G9 -> 0.28 | I9: =E9/(G9/3.6) -> 1.008 | J9: 0.78409091 | L9: 1.2 | M9: =SLOPE($E$3:$E$120, $D$3:$D$120) * L9 + INTERCEPT($E$3:$E$120, $D$3:$D$120) -> 6.7213946
B10: 212 | C10: Car | D10: 0.8 | E10: 3.62 | F10: 3.8222222 | G10: 17.2 | H10: =E10/G10 -> 0.21046512 | I10: =E10/(G10/3.6) -> 0.75767442 | J10: 0.5815793 | L10: 1.4 | M10: =SLOPE($E$3:$E$120, $D$3:$D$120) * L10 + INTERCEPT($E$3:$E$120, $D$3:$D$120) -> 7.670942
B11: 233 | C11: Car | D11: 1.48 | E11: 4.81 | F11: 6.2077778 | G11: 15.1 | H11: =E11/G11 -> 0.31854305 | I11: =E11/(G11/3.6) -> 1.146755 | J11: 0.79497331 | L11: 1.6 | M11: =SLOPE($E$3:$E$120, $D$3:$D$120) * L11 + INTERCEPT($E$3:$E$120, $D$3:$D$120) -> 8.6204895
A12: 3.35L3 | B12: 22 | C12: Car | D12: 1.8 | E12: 8.22 | F12: 10.2 | G12: 20.4 | H12: =E12/G12 -> 0.40294118 | I12: =E12/(G12/3.6) -> 1.4505882 | J12: 1.266673 | L12: 1.8 | M12: =SLOPE($E$3:$E$120, $D$3:$D$120) * L12 + INTERCEPT($E$3:$E$120, $D$3:$D$120) -> 9.5700369
B13: 33 | C13: Car | D13: 1.08 | E13: 3.4 | F13: 4.74 | G13: 15.8 | H13: =E13/G13 -> 0.21518987 | I13: =E13/(G13/3.6) -> 0.77468354 | J13: 0.55660249 | L13: 2 | M13: =SLOPE($E$3:$E$120, $D$3:$D$120) * L13 + INTERCEPT($E$3:$E$120, $D$3:$D$120) -> 10.519584
B14: 80 | C14: Car | D14: 2.04 | E14: 8.91 | F14: 13.6 | G14: 24 | H14: =E14/G14 -> 0.37125 | I14: =E14/(G14/3.6) -> 1.3365 | J14: 1.3126922
B15: 127 | C15: Car | D15: 1.8 | E15: 7.97 | F15: 6.95 | G15: 13.9 | H15: =E15/G15 -> 0.57338129 | I15: =E15/(G15/3.6) -> 2.0641727 | J15: 1.3392395
A16: 3.01 | B16: 62 | C16: Car | D16: 1.24 | E16: 8.11 | F16: 6.2 | G16: 18 | H16: =E16/G16 -> 0.45055556 | I16: =E16/(G16/3.6) -> 1.622 | J16: 1.2892081
B17: 10 | C17: Car | D17: 1.36 | E17: 3.83 | F17: 6.4222222 | G17: 17 | H17: =E17/G17 -> 0.22529412 | I17: =E17/(G17/3.6) -> 0.81105882 | J17: 0.61695904
B18: 61 | C18: Car | D18: 1.6 | E18: 9.01 | F18: 6.3111111 | G18: 14.2 | H18: =E18/G18 -> 0.63450704 | I18: =E18/(G18/3.6) -> 2.2842254 | J18: 1.5077016
B19: 82 | C19: Car | D19: 0.04 | E19: 0.26 | F19: 0.20777778 | G19: 18.7 | H19: =E19/G19 -> 0.013903743 | I19: =E19/(G19/3.6) -> 0.050053476 | J19: 0.040953561
B20: 92 | C20: Car | D20: 2.08 | E20: 10.18 | F20: 8.6088889 | G20: 14.9 | H20: =E20/G20 -> 0.68322148 | I20: =E20/(G20/3.6) -> 2.4595973 | J20: 1.6871191
B21: 109 | C21: Car | D21: 2.88 | E21: 13.04 | F21: 17.28 | G21: 21.6 | H21: =E21/G21 -> 0.6037037 | I21: =E21/(G21/3.6) -> 2.1733333 | J21: 1.9791101
B22: 161 | C22: Car | D22: 1.8 | E22: 7.9 | F22: 9.75 | G22: 19.5 | H22: =E22/G22 -> 0.40512821 | I22: =E22/(G22/3.6) -> 1.4584615 | J22: 1.2315066
B23: 260 | C23: Car | D23: 2 | E23: 11.64 | F23: 14 | G23: 25.2 | H23: =E23/G23 -> 0.46190476 | I23: =E23/(G23/3.6) -> 1.6628571 | J23: 1.6901515
A24: 8.15 | B24: 4 | C24: Car | D24: 1.96 | E24: 11.34 | F24: 12.848889 | G24: 23.6 | H24: =E24/G24 -> 0.48050847 | I24: =E24/(G24/3.6) -> 1.7298305 | J24: 1.6788928
B25: 6 | C25: Car | D25: 0.6 | E25: 4.52 | F25: 2.6833333 | G25: 16.1 | H25: =E25/G25 -> 0.28074534 | I25: =E25/(G25/3.6) -> 1.0106832 | J25: 0.73695652
B26: 15 | C26: Car | D26: 0.92 | E26: 1.5 | F26: 7.9988889 | G26: 31.3 | H26: =E26/G26 -> 0.047923323 | I26: =E26/(G26/3.6) -> 0.17252396 | J26: 0.20291844
B27: 23 | C27: Car | D27: 1.08 | E27: 9.11 | F27: 5.94 | G27: 19.8 | H27: =E27/G27 -> 0.46010101 | I27: =E27/(G27/3.6) -> 1.6563636 | J27: 1.4146508
B28: 90 | C28: Car | D28: 1.88 | E28: 11.21 | F28: 13.264444 | G28: 25.4 | H28: =E28/G28 -> 0.44133858 | I28: =E28/(G28/3.6) -> 1.5888189 | J28: 1.6238094
B29: 137 | C29: Car | D29: 3.12 | E29: 16.72 | F29: 19.673333 | G29: 22.7 | H29: =E29/G29 -> 0.73656388 | I29: =E29/(G29/3.6) -> 2.65163 | J29: 2.503025
B30: 165 | C30: Car | D30: 2.32 | E30: 16.59 | F30: 19.011111 | G30: 29.5 | H30: =E30/G30 -> 0.56237288 | I30: =E30/(G30/3.6) -> 2.0245424 | J30: 2.2904671
B31: 177 | C31: Car | D31: 2.76 | E31: 17.5 | F31: 21.62 | G31: 28.2 | H31: =E31/G31 -> 0.62056738 | I31: =E31/(G31/3.6) -> 2.2340426 | J31: 2.4525592
B32: 188 | C32: Car | D32: 2.04 | E32: 13.26 | F32: 14.79 | G32: 26.1 | H32: =E32/G32 -> 0.50804598 | I32: =E32/(G32/3.6) -> 1.8289655 | J32: 1.9047645
A33: 8.15L3 | B33: 147 | C33: Car | D33: 1.76 | E33: 10.95 | F33: 11.44 | G33: 23.4 | H33: =E33/G33 -> 0.46794872 | I33: =E33/(G33/3.6) -> 1.6846154 | J33: 1.6251383
A34: 8.58 | B34: 13 | C34: Car | D34: 2.88 | E34: 16.64 | F34: 15.28 | G34: 19.1 | H34: =E34/G34 -> 0.87120419 | I34: =E34/(G34/3.6) -> 3.1363351 | J34: 2.6074228
B35: 3 | C35: Car | D35: 0.2 | E35: 1.67 | F35: 0.82222222 | G35: 14.8 | H35: =E35/G35 -> 0.11283784 | I35: =E35/(G35/3.6) -> 0.40621622 | J35: 0.27714747
B36: 18 | C36: Car | D36: 3.04 | E36: 12.69 | F36: 17.057778 | G36: 20.2 | H36: =E36/G36 -> 0.62821782 | I36: =E36/(G36/3.6) -> 2.2615842 | J36: 1.9604881
B37: 54 | C37: Car | D37: 1.36 | E37: 8.36 | F37: 8.3488889 | G37: 22.1 | H37: =E37/G37 -> 0.37828054 | I37: =E37/(G37/3.6) -> 1.36181 | J37: 1.2608918
B38: 162 | C38: Car | D38: 1.44 | E38: 11.96 | F38: 11.76 | G38: 29.4 | H38: =E38/G38 -> 0.40680272 | I38: =E38/(G38/3.6) -> 1.4644898 | J38: 1.653125
B39: 211 | C39: Car | D39: 2.28 | E39: 13.82 | F39: 17.416667 | G39: 27.5 | H39: =E39/G39 -> 0.50254545 | I39: =E39/(G39/3.6) -> 1.8091636 | J39: 1.9526855
B40: 259 | C40: Car | D40: 2 | E40: 11.4 | F40: 8.5 | G40: 15.3 | H40: =E40/G40 -> 0.74509804 | I40: =E40/(G40/3.6) -> 2.6823529 | J40: 1.9604881
...

Sheet Bike L3
A1: Time | B1: ID | C1: Vehicle | D1: Headway | E1: Gap | F1: Gap (deduced) | G1: Speed | H1: Gap/ Speed(kmph) | I1: Gap/ Speed(mps) | J1: Min spacing
A2: 8.15 | B2: - | C2: - | D2: 0 | E2: 0 | F2: 0 | G2: - | H2: 0 | I2: 0 | J2: 0 | L2: Headway | M2: Gap (m)
B3: 50 | C3: Motorbike | D3: 0.4 | E3: 4.54 | F3: 3.811111 | G3: 34.299999 | H3: =E3/G3 -> 0.13236152 | I3: =E3/(G3/3.6) -> 0.47650146 | J3: 0.59419575 | L3: 0 | M3: 0
B4: 76 | C4: Motorbike | D4: 0.2 | E4: 0.28 | F4: 1.2722222 | G4: 22.9 | H4: =E4/G4 -> 0.012227074 | I4: =E4/(G4/3.6) -> 0.044017468 | J4: 0.041813011 | L4: 0.1 | M4: =SLOPE($E$2:$E$28, $D$2:$D$28) * L4 + INTERCEPT($E$2:$E$28, $D$2:$D$28) -> 0.6109657
B5: 96 | C5: Motorbike | D5: 0.44 | E5: 1.76 | F5: 3.0677778 | G5: 25.1 | H5: =E5/G5 -> 0.07011952 | I5: =E5/(G5/3.6) -> 0.25243027 | J5: 0.25586323 | L5: 0.2 | M5: =SLOPE($E$2:$E$28, $D$2:$D$28) * L5 + INTERCEPT($E$2:$E$28, $D$2:$D$28) -> 1.2936133
A6: 8.58 | B6: 11 | C6: Motorbike | D6: 1.16 | E6: 6.46 | F6: 7.7655557 | G6: 24.1 | H6: =E6/G6 -> 0.26804979 | I6: =E6/(G6/3.6) -> 0.96497924 | J6: 0.95057885 | L6: 0.3 | M6: =SLOPE($E$2:$E$28, $D$2:$D$28) * L6 + INTERCEPT($E$2:$E$28, $D$2:$D$28) -> 1.976261
B7: 34 | C7: Motorbike | D7: 0.96 | E7: 6.5900002 | F7: 6.3466665 | G7: 23.799999 | H7: =E7/G7 -> 0.27689077 | I7: =E7/(G7/3.6) -> 0.99680678 | J7: 0.9732663 | L7: 0.4 | M7: =SLOPE($E$2:$E$28, $D$2:$D$28) * L7 + INTERCEPT($E$2:$E$28, $D$2:$D$28) -> 2.6589086
B8: 48 | C8: Motorbike | D8: 0.08 | E8: 0.28999999 | F8: 0.44444444 | G8: 20 | H8: =E8/G8 -> 0.0145 | I8: =E8/(G8/3.6) -> 0.052199998 | J8: 0.044917264 | L8: 0.5 | M8: =SLOPE($E$2:$E$28, $D$2:$D$28) * L8 + INTERCEPT($E$2:$E$28, $D$2:$D$28) -> 3.3415562
B9: 31 | C9: Motorbike | D9: 0.56 | E9: 5.0500002 | F9: 2.4422222 | G9: 15.7 | H9: =E9/G9 -> 0.32165607 | I9: =E9/(G9/3.6) -> 1.1579618 | J9: 0.82784079 | L9: 0.6 | M9: =SLOPE($E$2:$E$28, $D$2:$D$28) * L9 + INTERCEPT($E$2:$E$28, $D$2:$D$28) -> 4.0242038
B10: 58 | C10: Motorbike | D10: 0.44 | E10: 1.86 | F10: 2.6033332 | G10: 21.299999 | H10: =E10/G10 -> 0.087323947 | I10: =E10/(G10/3.6) -> 0.31436621 | J10: 0.28336488 | L10: 0.7 | M10: =SLOPE($E$2:$E$28, $D$2:$D$28) * L10 + INTERCEPT($E$2:$E$28, $D$2:$D$28) -> 4.7068515
B11: 89 | C11: Motorbike | D11: 1.16 | E11: 6.6500001 | F11: 7.25 | G11: 22.5 | H11: =E11/G11 -> 0.29555556 | I11: =E11/(G11/3.6) -> 1.064 | J11: 0.99799591 | L11: 0.8 | M11: =SLOPE($E$2:$E$28, $D$2:$D$28) * L11 + INTERCEPT($E$2:$E$28, $D$2:$D$28) -> 5.3894991
B12: 82 | C12: Motorbike | D12: 0.6 | E12: 4.98 | F12: 1.4833333 | G12: 8.8999996 | H12: =E12/G12 -> 0.55955059 | I12: =E12/(G12/3.6) -> 2.0143821 | J12: 0.89939427 | L12: 0.9 | M12: =SLOPE($E$2:$E$28, $D$2:$D$28) * L12 + INTERCEPT($E$2:$E$28, $D$2:$D$28) -> 6.0721467
B13: 139 | C13: Motorbike | D13: 0.32 | E13: 2.4300001 | F13: 1.9111111 | G13: 21.5 | H13: =E13/G13 -> 0.11302326 | I13: =E13/(G13/3.6) -> 0.40688373 | J13: 0.36927071 | L13: 1 | M13: =SLOPE($E$2:$E$28, $D$2:$D$28) * L13 + INTERCEPT($E$2:$E$28, $D$2:$D$28) -> 6.7547944
B14: 117 | C14: Motorbike | D14: 0.68 | E14: 4.02 | F14: 4.7222222 | G14: 25 | H14: =E14/G14 -> 0.1608 | I14: =E14/(G14/3.6) -> 0.57888 | J14: 0.58511933
B15: 146 | C15: Motorbike | D15: 1 | E15: 5.52 | F15: 8.1388887 | G15: 29.299999 | H15: =E15/G15 -> 0.18839591 | I15: =E15/(G15/3.6) -> 0.67822527 | J15: 0.76385515
B16: 183 | C16: Motorbike | D16: 1.12 | E16: 7.8099999 | F16: 10.546667 | G16: 33.900002 | H16: =E16/G16 -> 0.23038347 | I16: =E16/(G16/3.6) -> 0.82938049 | J16: 1.0266247
B17: 122 | C17: Motorbike | D17: 1.6 | E17: 15.13 | F17: 7.6888885 | G17: 17.299999 | H17: =E17/G17 -> 0.87456652 | I17: =E17/(G17/3.6) -> 3.1484395 | J17: 2.4275147
B18: 208 | C18: Motorbike | D18: 1.68 | E18: 8.7399998 | F18: 14 | G18: 30 | H18: =E18/G18 -> 0.29133333 | I18: =E18/(G18/3.6) -> 1.0488 | J18: 1.1998124
B19: 221 | C19: Motorbike | D19: 0.92 | E19: 7.98 | F19: 6.3122224 | G19: 24.700001 | H19: =E19/G19 -> 0.32307691 | I19: =E19/(G19/3.6) -> 1.1630769 | J19: 1.165721
B20: 248 | C20: Motorbike | D20: 1.12 | E20: 8.7299995 | F20: 8.8044442 | G20: 28.299999 | H20: =E20/G20 -> 0.30848056 | I20: =E20/(G20/3.6) -> 1.11053 | J20: 1.2220583
A21: 9.03 | B21: 17 | C21: Motorbike | D21: 0.2 | E21: 1.77 | F21: 1.1944444 | G21: 21.5 | H21: =E21/G21 -> 0.082325581 | I21: =E21/(G21/3.6) -> 0.29637209 | J21: 0.26897495
B22: 33 | C22: Motorbike | D22: 0.48 | E22: 3.1900001 | F22: 2.9733332 | G22: 22.299999 | H22: =E22/G22 -> 0.14304933 | I22: =E22/(G22/3.6) -> 0.51497761 | J22: 0.47993086
B23: 27 | C23: Motorbike | D23: 1 | E23: 7.21 | F23: 5.7777776 | G23: 20.799999 | H23: =E23/G23 -> 0.34663463 | I23: =E23/(G23/3.6) -> 1.2478847 | J23: 1.105393
B24: 144 | C24: Motorbike | D24: 0.6 | E24: 4.8099999 | F24: 3.2000001 | G24: 19.200001 | H24: =E24/G24 -> 0.25052082 | I24: =E24/(G24/3.6) -> 0.90187495 | J24: 0.75273132
B25: 276 | C25: Motorbike | D25: 1.48 | E25: 9.1899996 | F25: 7.1533332 | G25: 17.4 | H25: =E25/G25 -> 0.52816091 | I25: =E25/(G25/3.6) -> 1.9013793 | J25: 1.4725218
A26: 17.21 | B26: 12 | C26: Motorbike | D26: 0.6 | E26: 2.85 | F26: 3.6833333 | G26: 22.1 | H26: =E26/G26 -> 0.12895928 | I26: =E26/(G26/3.6) -> 0.46425339 | J26: 0.42984949
B27: 30 | C27: Motorbike | D27: 0.8 | E27: 4.34 | F27: 5.4 | G27: 24.3 | H27: =E27/G27 -> 0.17860082 | I27: =E27/(G27/3.6) -> 0.64296296 | J27: 0.63707148
B28: 35 | C28: Motorbike | D28: 1 | E28: 6.51 | F28: 6.75 | G28: 24.3 | H28: =E28/G28 -> 0.26790123 | I28: =E28/(G28/3.6) -> 0.96444444 | J28: 0.95560722
P38: Time - Space Headway Relation (Two-wheelers)
P39: Headway (seconds) | Q39: Gap/ Speed | R39: Speed (km/h)
R40: 17 | S40: 18 | T40: 19 | U40: 20 | V40: 21
P41: 0 | Q41: 0 | R41: 0 | S41: 0 | T41: 0 | U41: 0 | V41: 0
P42: 0.1 | Q42: =SLOPE($H$2:$H$98, $D$2:$D$98) * P42 + INTERCEPT($H$2:$H$98, $D$2:$D$98) -> 0.036872479 | R42: =$R$40*Q42 -> 0.62683215 | S42: =$S$40*Q42 -> 0.66370463 | T42: =$T$40*Q42 -> 0.7005771 | U42: =$U$40*Q42 -> 0.73744958 | V42: =$V$40*Q42 -> 0.77432206
P43: 0.2 | Q43: =SLOPE($H$2:$H$98, $D$2:$D$98) * P43 + INTERCEPT($H$2:$H$98, $D$2:$D$98) -> 0.067369074 | R43: =$R$40*Q43 -> 1.1452743 | S43: =$S$40*Q43 -> 1.2126433 | T43: =$T$40*Q43 -> 1.2800124 | U43: =$U$40*Q43 -> 1.3473815 | V43: =$V$40*Q43 -> 1.4147506
P44: 0.3 | Q44: =SLOPE($H$2:$H$98, $D$2:$D$98) * P44 + INTERCEPT($H$2:$H$98, $D$2:$D$98) -> 0.097865669 | R44: =$R$40*Q44 -> 1.6637164 | S44: =$S$40*Q44 -> 1.761582 | T44: =$T$40*Q44 -> 1.8594477 | U44: =$U$40*Q44 -> 1.9573134 | V44: =$V$40*Q44 -> 2.055179
P45: 0.4 | Q45: =SLOPE($H$2:$H$98, $D$2:$D$98) * P45 + INTERCEPT($H$2:$H$98, $D$2:$D$98) -> 0.12836226 | R45: =$R$40*Q45 -> 2.1821585 | S45: =$S$40*Q45 -> 2.3105207 | T45: =$T$40*Q45 -> 2.438883 | U45: =$U$40*Q45 -> 2.5672453 | V45: =$V$40*Q45 -> 2.6956075
M46: Avg | N46: =AVERAGEIF($G$3:$G$98,">0") -> 23.096154 | P46: 0.5 | Q46: =SLOPE($H$2:$H$98, $D$2:$D$98) * P46 + INTERCEPT($H$2:$H$98, $D$2:$D$98) -> 0.15885886 | R46: =$R$40*Q46 -> 2.7006006 | S46: =$S$40*Q46 -> 2.8594594 | T46: =$T$40*Q46 -> 3.0183183 | U46: =$U$40*Q46 -> 3.1771772 | V46: =$V$40*Q46 -> 3.336036
M47: Min | N47: =MIN($G$3:$G$98) -> 8.8999996 | P47: 0.6 | Q47: =SLOPE($H$2:$H$98, $D$2:$D$98) * P47 + INTERCEPT($H$2:$H$98, $D$2:$D$98) -> 0.18935545 | R47: =$R$40*Q47 -> 3.2190427 | S47: =$S$40*Q47 -> 3.4083982 | T47: =$T$40*Q47 -> 3.5977536 | U47: =$U$40*Q47 -> 3.7871091 | V47: =$V$40*Q47 -> 3.9764645
M48: Max | N48: =MAX($G$3:$G$98) -> 34.299999 | P48: 0.7 | Q48: =SLOPE($H$2:$H$98, $D$2:$D$98) * P48 + INTERCEPT($H$2:$H$98, $D$2:$D$98) -> 0.21985205 | R48: =$R$40*Q48 -> 3.7374848 | S48: =$S$40*Q48 -> 3.9573369 | T48: =$T$40*Q48 -> 4.1771889 | U48: =$U$40*Q48 -> 4.397041 | V48: =$V$40*Q48 -> 4.616893
M49: 25th perc | N49: =_xlfn.PERCENTILE.EXC($G$3:$G$98,0.25) -> 20.599999 | P49: 0.8 | Q49: =SLOPE($H$2:$H$98, $D$2:$D$98) * P49 + INTERCEPT($H$2:$H$98, $D$2:$D$98) -> 0.25034864 | R49: =$R$40*Q49 -> 4.2559269 | S49: =$S$40*Q49 -> 4.5062756 | T49: =$T$40*Q49 -> 4.7566242 | U49: =$U$40*Q49 -> 5.0069728 | V49: =$V$40*Q49 -> 5.2573215
...

Sheet 3.35
A1: Lane 2 | X1: Headway | Z1: Speed | AB1: Vehicle Type
A2: L2_ID | B2: L2_Cls | C2: L2_Time | D2: Headway | E2: L2_Gap | F2: Gap (Calc) | G2: L2_Speed | J2: Headway | K2: Gap (m) | X2: Time | Y2: Gap | Z2: Leader | AA2: Follower | AB2: Leader | AC2: Follower
A3: 9 | B3: Motorbike | C3: 1.48 | D3: 0 | E3: 0 | F3: 0 | G3: 23.9 | J3: 0 | K3: 0 | X3: =D4 -> 0.4 | Y3: =E4 -> 2.13 | Z3: =G4 -> 21.1 | AA3: =G3 -> 23.9 | AB3: Car | AC3: Car
A4: 17 | B4: Motorbike | C4: 1.88 | D4: =C4-C3 -> 0.4 | E4: 2.13 | F4: =D4*G4/3.6 -> 2.3444444 | G4: 21.1 | H4: =ABS(G4-G3) -> 2.8 | J4: 0.2 | K4: =SLOPE($E$3:$E$27, $D$3:$D$27) * J4 + INTERCEPT($E$3:$E$27, $D$3:$D$27) -> 1.096089 | X4: =D5 -> 1.04 | Y4: =E5 -> 3.33 | Z4: =G5 -> 26.9 | AA4: =G4 -> 21.1 | AB4: Car | AC4: Car
A5: 3 | B5: Car | C5: 2.92 | D5: =C5-C4 -> 1.04 | E5: 3.33 | F5: =D5*G5/3.6 -> 7.7711111 | G5: 26.9 | H5: =ABS(G5-G4) -> 5.8 | J5: 0.4 | K5: =SLOPE($E$3:$E$27, $D$3:$D$27) * J5 + INTERCEPT($E$3:$E$27, $D$3:$D$27) -> 1.9297425 | X5: =D6 -> 1.16 | Y5: =E6 -> 9.33 | Z5: =G6 -> 17.9 | AA5: =G5 -> 26.9 | AB5: Car | AC5: Car
A6: 21 | B6: Motorbike | C6: 4.08 | D6: =C6-C5 -> 1.16 | E6: 9.33 | F6: =D6*G6/3.6 -> 5.7677778 | G6: 17.9 | H6: =ABS(G6-G5) -> 9 | J6: 0.6 | K6: =SLOPE($E$3:$E$27, $D$3:$D$27) * J6 + INTERCEPT($E$3:$E$27, $D$3:$D$27) -> 2.7633961 | X6: =D7 -> 1.24 | Y6: =E7 -> 5.05 | Z6: =G7 -> 19 | AA6: =G6 -> 17.9
A7: 4 | B7: Car | C7: 5.32 | D7: =C7-C6 -> 1.24 | E7: 5.05 | F7: =D7*G7/3.6 -> 6.5444444 | G7: 19 | H7: =ABS(G7-G6) -> 1.1 | J7: 0.8 | K7: =SLOPE($E$3:$E$27, $D$3:$D$27) * J7 + INTERCEPT($E$3:$E$27, $D$3:$D$27) -> 3.5970496 | X7: =D8 -> 2.16 | Y7: =E8 -> 9.4 | Z7: =G8 -> 16.6 | AA7: =G7 -> 19
A8: 12 | B8: Car | C8: 7.48 | D8: =C8-C7 -> 2.16 | E8: 9.4 | F8: =D8*G8/3.6 -> 9.96 | G8: 16.6 | H8: =ABS(G8-G7) -> 2.4 | J8: 1 | K8: =SLOPE($E$3:$E$27, $D$3:$D$27) * J8 + INTERCEPT($E$3:$E$27, $D$3:$D$27) -> 4.4307032 | X8: =D9 -> 2.64 | Y8: =E9 -> 10.42 | Z8: =G9 -> 17.6 | AA8: =G8 -> 16.6
A9: 52 | B9: Car | C9: 10.12 | D9: =C9-C8 -> 2.64 | E9: 10.42 | F9: =D9*G9/3.6 -> 12.906667 | G9: 17.6 | H9: =ABS(G9-G8) -> 1 | J9: 1.2 | K9: =SLOPE($E$3:$E$27, $D$3:$D$27) * J9 + INTERCEPT($E$3:$E$27, $D$3:$D$27) -> 5.2643567 | X9: =D10 -> 2.2 | Y9: =E10 -> 6.72 | Z9: =G10 -> 16.2 | AA9: =G9 -> 17.6
A10: 85 | B10: Truck | C10: 12.32 | D10: =C10-C9 -> 2.2 | E10: 6.72 | F10: =D10*G10/3.6 -> 9.9 | G10: 16.2 | H10: =ABS(G10-G9) -> 1.4 | J10: 1.4 | K10: =SLOPE($E$3:$E$27, $D$3:$D$27) * J10 + INTERCEPT($E$3:$E$27, $D$3:$D$27) -> 6.0980103 | X10: =D11 -> 2.68 | Y10: =E11 -> 11.78 | Z10: =G11 -> 21.8 | AA10: =G10 -> 16.2
A11: 97 | B11: Car | C11: 15 | D11: =C11-C10 -> 2.68 | E11: 11.78 | F11: =D11*G11/3.6 -> 16.228889 | G11: 21.8 | H11: =ABS(G11-G10) -> 5.6 | J11: 1.6 | K11: =SLOPE($E$3:$E$27, $D$3:$D$27) * J11 + INTERCEPT($E$3:$E$27, $D$3:$D$27) -> 6.9316638 | X11: =D12 -> 1.48 | Y11: =E12 -> 6.75 | Z11: =G12 -> 17.6 | AA11: =G11 -> 21.8
A12: 106 | B12: CNG | C12: 16.48 | D12: =C12-C11 -> 1.48 | E12: 6.75 | F12: =D12*G12/3.6 -> 7.2355556 | G12: 17.6 | H12: =ABS(G12-G11) -> 4.2 | J12: 1.8 | K12: =SLOPE($E$3:$E$27, $D$3:$D$27) * J12 + INTERCEPT($E$3:$E$27, $D$3:$D$27) -> 7.7653174 | X12: =D13 -> 1.64 | Y12: =E13 -> 5.56 | Z12: =G13 -> 20.5 | AA12: =G12 -> 17.6
A13: 126 | B13: Car | C13: 18.12 | D13: =C13-C12 -> 1.64 | E13: 5.56 | F13: =D13*G13/3.6 -> 9.3388889 | G13: 20.5 | H13: =ABS(G13-G12) -> 2.9 | J13: 2 | K13: =SLOPE($E$3:$E$27, $D$3:$D$27) * J13 + INTERCEPT($E$3:$E$27, $D$3:$D$27) -> 8.5989709 | X13: =D14 -> 1.68 | Y13: =E14 -> 8.88 | Z13: =G14 -> 24 | AA13: =G13 -> 20.5
A14: 120 | B14: Car | C14: 19.8 | D14: =C14-C13 -> 1.68 | E14: 8.88 | F14: =D14*G14/3.6 -> 11.2 | G14: 24 | H14: =ABS(G14-G13) -> 3.5 | X14: =D15 -> 1.68 | Y14: =E15 -> 11 | Z14: =G15 -> 20 | AA14: =G14 -> 24
A15: 153 | B15: CNG | C15: 21.48 | D15: =C15-C14 -> 1.68 | E15: 11 | F15: =D15*G15/3.6 -> 9.3333333 | G15: 20 | H15: =ABS(G15-G14) -> 4 | J15: Time Mean Speed | X15: =D16 -> 1 | Y15: =E16 -> 3.12 | Z15: =G16 -> 19.8 | AA15: =G15 -> 20
A16: 142 | B16: Car | C16: 22.48 | D16: =C16-C15 -> 1 | E16: 3.12 | F16: =D16*G16/3.6 -> 5.5 | G16: 19.8 | H16: =ABS(G16-G15) -> 0.2 | J16: Car | K16: =AVERAGEIFS($G$3:$G$30, $B$3:$B$30, J16, $G$3:$G$30, "<>0") -> 19.586667 | X16: =D17 -> 3.44 | Y16: =E17 -> 15.85 | Z16: =G17 -> 16.6 | AA16: =G16 -> 19.8
A17: 157 | B17: CNG | C17: 25.92 | D17: =C17-C16 -> 3.44 | E17: 15.85 | F17: =D17*G17/3.6 -> 15.862222 | G17: 16.6 | H17: =ABS(G17-G16) -> 3.2 | J17: Motorbike | K17: =AVERAGEIFS($G$3:$G$30, $B$3:$B$30, J17, $G$3:$G$30, "<>0") -> 19.475 | X17: =D18 -> 1.2 | Y17: =E18 -> 4.82 | Z17: =G18 -> 33 | AA17: =G17 -> 16.6
A18: 162 | B18: Car | C18: 27.12 | D18: =C18-C17 -> 1.2 | E18: 4.82 | F18: =D18*G18/3.6 -> 11 | G18: 33 | H18: =ABS(G18-G17) -> 16.4 | J18: CNG | K18: =AVERAGEIFS($G$3:$G$30, $B$3:$B$30, J18, $G$3:$G$30, "<>0") -> 18.066667 | X18: =D19 -> 2.68 | Y18: =E19 -> 11.16 | Z18: =G19 -> 17.4 | AA18: =G18 -> 33
A19: 189 | B19: Car | C19: 29.8 | D19: =C19-C18 -> 2.68 | E19: 11.16 | F19: =D19*G19/3.6 -> 12.953333 | G19: 17.4 | H19: =ABS(G19-G18) -> 15.6 | X19: =D20 -> 1.6 | Y19: =E20 -> 7.12 | Z19: =G20 -> 15.5 | AA19: =G19 -> 17.4
A20: 177 | B20: Car | C20: 31.4 | D20: =C20-C19 -> 1.6 | E20: 7.12 | F20: =D20*G20/3.6 -> 6.8888889 | G20: 15.5 | H20: =ABS(G20-G19) -> 1.9 | X20: =D21 -> 1.6 | Y20: =E21 -> 5.01 | Z20: =G21 -> 11.9 | AA20: =G20 -> 15.5
A21: 197 | B21: Car | C21: 33 | D21: =C21-C20 -> 1.6 | E21: 5.01 | F21: =D21*G21/3.6 -> 5.2888889 | G21: 11.9 | H21: =ABS(G21-G20) -> 3.6 | X21: =D22 -> 1.2 | Y21: =E22 -> 4.9 | Z21: =G22 -> 17.5 | AA21: =G21 -> 11.9
A22: 203 | B22: Car | C22: 34.2 | D22: =C22-C21 -> 1.2 | E22: 4.9 | F22: =D22*G22/3.6 -> 5.8333333 | G22: 17.5 | H22: =ABS(G22-G21) -> 5.6 | X22: =D23 -> 0.8 | Y22: =E23 -> 3.62 | Z22: =G23 -> 17.2 | AA22: =G22 -> 17.5
A23: 212 | B23: Car | C23: 35 | D23: =C23-C22 -> 0.8 | E23: 3.62 | F23: =D23*G23/3.6 -> 3.8222222 | G23: 17.2 | H23: =ABS(G23-G22) -> 0.3 | X23: =D24 -> 1.48 | Y23: =E24 -> 4.81 | Z23: =G24 -> 15.1 | AA23: =G23 -> 17.2
A24: 233 | B24: Car | C24: 36.48 | D24: =C24-C23 -> 1.48 | E24: 4.81 | F24: =D24*G24/3.6 -> 6.2077778 | G24: 15.1 | H24: =ABS(G24-G23) -> 2.1 | X24: =D25 -> 0.8 | Y24: =E25 -> 4.5 | Z24: =G25 -> 15 | AA24: =G24 -> 15.1
A25: 242 | B25: Motorbike | C25: 37.28 | D25: =C25-C24 -> 0.8 | E25: 4.5 | F25: =D25*G25/3.6 -> 3.3333333 | G25: 15 | H25: =ABS(G25-G24) -> 0.1 | X25: =D26 -> 0 | Y25: =E26 -> 0 | Z25: =G26 -> 0 | AA25: =G25 -> 15
X26: =D27 -> 0 | Y26: =E27 -> 0 | Z26: =G27 -> 0 | AA26: =G26 -> 0
X27: =D28 -> 0 | Y27: =E28 -> 0 | Z27: =G28 -> 0 | AA27: =G27 -> 0
AB31: Normalizing Gap by speed | AD31: Gap
Y32: Gap/V | Z32: Headway | AB32: Headway | AC32: Gap/V | AD32: 15 | AE32: 18 | AF32: 20 | AG32: 25
A33: Lane 3 | J33: Headway | K33: Gap (m) | Y33: 0 | Z33: 0 | AB33: 0 | AC33: 0 | AD33: 0 | AE33: 0 | AF33: 0 | AG33: 0
A34: L3_ID | B34: L3_Cls | C34: L3_Time | D34: Headway | E34: L3_Gap | F34: Gap (Calc) | G34: L3_Speed | J34: 0 | K34: 0 | Y34: =E4/G4 -> 0.10094787 | Z34: 0.4 | AB34: 0.2 | AC34: =SLOPE($Y$33:$Y$57, $Z$33:$Z$57) * AB34 + INTERCEPT($Y$33:$Y$57, $Z$33:$Z$57) -> #DIV/0! | AD34: =$AD$32*AC34 -> #DIV/0! | AE34: =$AE$32*AC34 -> #DIV/0! | AF34: =$AF$32*AC34 -> #DIV/0! | AG34: =$AG$32*AC34 -> #DIV/0!
A35: 8 | B35: CNG | C35: 3.6 | D35: 0 | E35: 0 | F35: 0 | G35: 18.1 | J35: 0.2 | K35: =SLOPE($E$35:$E$58, $D$35:$D$58) * J35 + INTERCEPT($E$35:$E$58, $D$35:$D$58) -> 1.5838712 | Y35: =E5/G5 -> 0.12379182 | Z35: 1.04 | AB35: 0.4 | AC35: =SLOPE($Y$33:$Y$57, $Z$33:$Z$57) * AB35 + INTERCEPT($Y$33:$Y$57, $Z$33:$Z$57) -> #DIV/0! | AD35: =$AD$32*AC35 -> #DIV/0! | AE35: =$AE$32*AC35 -> #DIV/0! | AF35: =$AF$32*AC35 -> #DIV/0! | AG35: =$AG$32*AC35 -> #DIV/0!
A36: 56 | B36: Motorbike | C36: 4.6 | D36: =C36-C35 -> 1 | E36: 2.92 | F36: =D36*G36/3.6 -> 0 | G36: 0 | J36: 0.4 | K36: =SLOPE($E$35:$E$58, $D$35:$D$58) * J36 + INTERCEPT($E$35:$E$58, $D$35:$D$58) -> 2.1765536 | Y36: =E6/G6 -> 0.52122905 | Z36: 1.16 | AB36: 0.6 | AC36: =SLOPE($Y$33:$Y$57, $Z$33:$Z$57) * AB36 + INTERCEPT($Y$33:$Y$57, $Z$33:$Z$57) -> #DIV/0! | AD36: =$AD$32*AC36 -> #DIV/0! | AE36: =$AE$32*AC36 -> #DIV/0! | AF36: =$AF$32*AC36 -> #DIV/0! | AG36: =$AG$32*AC36 -> #DIV/0!
A37: 38 | B37: Motorbike | C37: 5.4 | D37: =C37-C36 -> 0.8 | E37: 5.23 | F37: =D37*G37/3.6 -> 4.2444444 | G37: 19.1 | J37: 0.6 | K37: =SLOPE($E$35:$E$58, $D$35:$D$58) * J37 + INTERCEPT($E$35:$E$58, $D$35:$D$58) -> 2.769236 | Y37: =E7/G7 -> 0.26578947 | Z37: 1.24 | AB37: 0.8 | AC37: =SLOPE($Y$33:$Y$57, $Z$33:$Z$57) * AB37 + INTERCEPT($Y$33:$Y$57, $Z$33:$Z$57) -> #DIV/0! | AD37: =$AD$32*AC37 -> #DIV/0! | AE37: =$AE$32*AC37 -> #DIV/0! | AF37: =$AF$32*AC37 -> #DIV/0! | AG37: =$AG$32*AC37 -> #DIV/0!
A38: 7 | B38: Car | C38: 5.72 | D38: =C38-C37 -> 0.32 | E38: 1.41 | F38: =D38*G38/3.6 -> 1.4755556 | G38: 16.6 | J38: 0.8 | K38: =SLOPE($E$35:$E$58, $D$35:$D$58) * J38 + INTERCEPT($E$35:$E$58, $D$35:$D$58) -> 3.3619184 | Y38: =E8/G8 -> 0.56626506 | Z38: 2.16 | AB38: 1 | AC38: =SLOPE($Y$33:$Y$57, $Z$33:$Z$57) * AB38 + INTERCEPT($Y$33:$Y$57, $Z$33:$Z$57) -> #DIV/0! | AD38: =$AD$32*AC38 -> #DIV/0! | AE38: =$AE$32*AC38 -> #DIV/0! | AF38: =$AF$32*AC38 -> #DIV/0! | AG38: =$AG$32*AC38 -> #DIV/0!
A39: 22 | B39: Car | C39: 7.52 | D39: =C39-C38 -> 1.8 | E39: 8.22 | F39: =D39*G39/3.6 -> 10.2 | G39: 20.4 | J39: 1 | K39: =SLOPE($E$35:$E$58, $D$35:$D$58) * J39 + INTERCEPT($E$35:$E$58, $D$35:$D$58) -> 3.9546008 | Y39: =E9/G9 -> 0.59204545 | Z39: 2.64 | AB39: 1.2 | AC39: =SLOPE($Y$33:$Y$57, $Z$33:$Z$57) * AB39 + INTERCEPT($Y$33:$Y$57, $Z$33:$Z$57) -> #DIV/0! | AD39: =$AD$32*AC39 -> #DIV/0! | AE39: =$AE$32*AC39 -> #DIV/0! | AF39: =$AF$32*AC39 -> #DIV/0! | AG39: =$AG$32*AC39 -> #DIV/0!
A40: 33 | B40: Car | C40: 8.6 | D40: =C40-C39 -> 1.08 | E40: 3.4 | F40: =D40*G40/3.6 -> 4.74 | G40: 15.8 | J40: 1.2 | K40: =SLOPE($E$35:$E$58, $D$35:$D$58) * J40 + INTERCEPT($E$35:$E$58, $D$35:$D$58) -> 4.5472832 | Y40: =E10/G10 -> 0.41481481 | Z40: 2.2 | AB40: 1.4 | AC40: =SLOPE($Y$33:$Y$57, $Z$33:$Z$57) * AB40 + INTERCEPT($Y$33:$Y$57, $Z$33:$Z$57) -> #DIV/0! | AD40: =$AD$32*AC40 -> #DIV/0! | AE40: =$AE$32*AC40 -> #DIV/0! | AF40: =$AF$32*AC40 -> #DIV/0! | AG40: =$AG$32*AC40 -> #DIV/0!
A41: 78 | B41: Motorbike | C41: 9.6 | D41: =C41-C40 -> 1 | E41: 5.75 | F41: =D41*G41/3.6 -> 4.8611111 | G41: 17.5 | J41: 1.4 | K41: =SLOPE($E$35:$E$58, $D$35:$D$58) * J41 + INTERCEPT($E$35:$E$58, $D$35:$D$58) -> 5.1399657 | Y41: =E11/G11 -> 0.54036697 | Z41: 2.68 | AB41: 1.6 | AC41: =SLOPE($Y$33:$Y$57, $Z$33:$Z$57) * AB41 + INTERCEPT($Y$33:$Y$57, $Z$33:$Z$57) -> #DIV/0! | AD41: =$AD$32*AC41 -> #DIV/0! | AE41: =$AE$32*AC41 -> #DIV/0! | AF41: =$AF$32*AC41 -> #DIV/0! | AG41: =$AG$32*AC41 -> #DIV/0!
A42: 60 | B42: CNG | C42: 11.48 | D42: =C42-C41 -> 1.88 | E42: 8.01 | F42: =D42*G42/3.6 -> 8.7733333 | G42: 16.8 | J42: 1.6 | K42: =SLOPE($E$35:$E$58, $D$35:$D$58) * J42 + INTERCEPT($E$35:$E$58, $D$35:$D$58) -> 5.7326481 | Y42: =E12/G12 -> 0.38352273 | Z42: 1.48 | AB42: 1.8 | AC42: =SLOPE($Y$33:$Y$57, $Z$33:$Z$57) * AB42 + INTERCEPT($Y$33:$Y$57, $Z$33:$Z$57) -> #DIV/0! | AD42: =$AD$32*AC42 -> #DIV/0! | AE42: =$AE$32*AC42 -> #DIV/0! | AF42: =$AF$32*AC42 -> #DIV/0! | AG42: =$AG$32*AC42 -> #DIV/0!
A43: 50 | B43: Car | C43: 12.68 | D43: =C43-C42 -> 1.2 | E43: 5.78 | F43: =D43*G43/3.6 -> 5.7 | G43: 17.1 | J43: 1.8 | K43: =SLOPE($E$35:$E$58, $D$35:$D$58) * J43 + INTERCEPT($E$35:$E$58, $D$35:$D$58) -> 6.3253305 | Y43: =E13/G13 -> 0.27121951 | Z43: 1.64 | AB43: 2 | AC43: =SLOPE($Y$33:$Y$57, $Z$33:$Z$57) * AB43 + INTERCEPT($Y$33:$Y$57, $Z$33:$Z$57) -> #DIV/0! | AD43: =$AD$32*AC43 -> #DIV/0! | AE43: =$AE$32*AC43 -> #DIV/0! | AF43: =$AF$32*AC43 -> #DIV/0! | AG43: =$AG$32*AC43 -> #DIV/0!
...

Sheet 3.01
A1: Lane 2 | X1: Headway | Z1: Speed | AC1: L1_ID | AD1: L1_Cls | AE1: L1_Time | AF1: L1_Speed | AG1: L1_Gap
A2: L2_ID | B2: L2_Cls | C2: L2_Time | D2: Headway | E2: L2_Gap | F2: Gap (Calc) | G2: L2_Speed | J2: Headway | K2: Gap (m) | X2: Time | Y2: Gap | Z2: Leader | AA2: Follower | AC2: 5 | AD2: Car | AE2: 5.32 | AF2: 14.5
A3: 71 | B3: Car | C3: 12.4 | D3: 0 | E3: 0 | F3: 0 | G3: 28.8 | J3: 0 | K3: 0 | X3: =D4 -> 1.24 | Y3: =E4 -> 8.11 | Z3: =G4 -> 18 | AA3: =G3 -> 28.8 | AC3: 2 | AD3: Car | AE3: 7.64 | AF3: 14.1 | AG3: 2.3599999
A4: 62 | B4: Car | C4: 13.64 | D4: =C4-C3 -> 1.24 | E4: 8.11 | F4: =D4*G4/3.6 -> 6.2 | G4: 18 | J4: 0.2 | K4: =SLOPE($E$3:$E$27, $D$3:$D$27) * J4 + INTERCEPT($E$3:$E$27, $D$3:$D$27) -> 3.4007837 | X4: =D5 -> 1.36 | Y4: =E5 -> 3.83 | Z4: =G5 -> 17 | AA4: =G4 -> 18 | AC4: 3 | AD4: Car | AE4: 8 | AF4: 13.2 | AG4: 3.6900001
A5: 10 | B5: Car | C5: 15 | D5: =C5-C4 -> 1.36 | E5: 3.83 | F5: =D5*G5/3.6 -> 6.4222222 | G5: 17 | J5: 0.4 | K5: =SLOPE($E$3:$E$27, $D$3:$D$27) * J5 + INTERCEPT($E$3:$E$27, $D$3:$D$27) -> 3.8960239 | X5: =D6 -> 1.6 | Y5: =E6 -> 9.01 | Z5: =G6 -> 14.2 | AA5: =G5 -> 17 | AC5: 14 | AD5: Truck | AE5: 10.2 | AF5: 19.6 | AG5: -0.27000001
A6: 61 | B6: Car | C6: 16.6 | D6: =C6-C5 -> 1.6 | E6: 9.01 | F6: =D6*G6/3.6 -> 6.3111111 | G6: 14.2 | J6: 0.6 | K6: =SLOPE($E$3:$E$27, $D$3:$D$27) * J6 + INTERCEPT($E$3:$E$27, $D$3:$D$27) -> 4.3912642 | X6: =D7 -> 0.04 | Y6: =E7 -> 0.26 | Z6: =G7 -> 18.7 | AA6: =G6 -> 14.2 | AC6: 64 | AD6: Car | AE6: 11.2 | AF6: 19.700001 | AG6: 8.5
A7: 82 | B7: Car | C7: 16.64 | D7: =C7-C6 -> 0.04 | E7: 0.26 | F7: =D7*G7/3.6 -> 0.20777778 | G7: 18.7 | J7: 0.8 | K7: =SLOPE($E$3:$E$27, $D$3:$D$27) * J7 + INTERCEPT($E$3:$E$27, $D$3:$D$27) -> 4.8865044 | X7: =D8 -> 2.08 | Y7: =E8 -> 10.18 | Z7: =G8 -> 14.9 | AA7: =G7 -> 18.7 | AC7: 69 | AD7: Car | AE7: 15 | AF7: 20.299999 | AG7: 19.719999
A8: 92 | B8: Car | C8: 18.72 | D8: =C8-C7 -> 2.08 | E8: 10.18 | F8: =D8*G8/3.6 -> 8.6088889 | G8: 14.9 | J8: 1 | K8: =SLOPE($E$3:$E$27, $D$3:$D$27) * J8 + INTERCEPT($E$3:$E$27, $D$3:$D$27) -> 5.3817447 | X8: =D9 -> 2.88 | Y8: =E9 -> 13.04 | Z8: =G9 -> 21.6 | AA8: =G8 -> 14.9 | AC8: 91 | AD8: Motorbike | AE8: 15.92 | AF8: 29.9 | AG8: 4.4400001
A9: 109 | B9: Car | C9: 21.6 | D9: =C9-C8 -> 2.88 | E9: 13.04 | F9: =D9*G9/3.6 -> 17.28 | G9: 21.6 | J9: 1.2 | K9: =SLOPE($E$3:$E$27, $D$3:$D$27) * J9 + INTERCEPT($E$3:$E$27, $D$3:$D$27) -> 5.8769849 | X9: =D10 -> 4.32 | Y9: =E10 -> 17.58 | Z9: =G10 -> 19.5 | AA9: =G9 -> 21.6 | AC9: 90 | AD9: Car | AE9: 16.52 | AF9: 19.200001 | AG9: 3.53
A10: 136 | B10: Car | C10: 25.92 | D10: =C10-C9 -> 4.32 | E10: 17.58 | F10: =D10*G10/3.6 -> 23.4 | G10: 19.5 | J10: 1.4 | K10: =SLOPE($E$3:$E$27, $D$3:$D$27) * J10 + INTERCEPT($E$3:$E$27, $D$3:$D$27) -> 6.3722252 | X10: =D11 -> 0.08 | Y10: =E11 -> -0.27 | Z10: =G11 -> 14.3 | AA10: =G10 -> 19.5 | AC10: 94 | AD10: Car | AE10: 18.52 | AF10: 25.700001 | AG10: 3.8499999
A11: 150 | B11: CNG | C11: 26 | D11: =C11-C10 -> 0.08 | E11: -0.27 | F11: =D11*G11/3.6 -> 0.31777778 | G11: 14.3 | J11: 1.6 | K11: =SLOPE($E$3:$E$27, $D$3:$D$27) * J11 + INTERCEPT($E$3:$E$27, $D$3:$D$27) -> 6.8674654 | X11: =D12 -> 1.24 | Y11: =E12 -> 6.01 | Z11: =G12 -> 21.7 | AA11: =G11 -> 14.3 | AC11: 99 | AD11: Car | AE11: 20.44 | AF11: 19.299999 | AG11: 10.14
A12: 177 | B12: Motorbike | C12: 27.24 | D12: =C12-C11 -> 1.24 | E12: 6.01 | F12: =D12*G12/3.6 -> 7.4744444 | G12: 21.7 | J12: 1.8 | K12: =SLOPE($E$3:$E$27, $D$3:$D$27) * J12 + INTERCEPT($E$3:$E$27, $D$3:$D$27) -> 7.3627057 | X12: =D13 -> 0.96 | Y12: =E13 -> 4.72 | Z12: =G13 -> 20 | AA12: =G12 -> 21.7 | AC12: 134 | AD12: CNG | AE12: 21.84 | AF12: 23.799999 | AG12: 5.5500002
A13: 148 | B13: Car | C13: 28.2 | D13: =C13-C12 -> 0.96 | E13: 4.72 | F13: =D13*G13/3.6 -> 5.3333333 | G13: 20 | J13: 2 | K13: =SLOPE($E$3:$E$27, $D$3:$D$27) * J13 + INTERCEPT($E$3:$E$27, $D$3:$D$27) -> 7.8579459 | X13: =D14 -> 1.8 | Y13: =E14 -> 7.9 | Z13: =G14 -> 19.5 | AA13: =G13 -> 20 | AC13: 112 | AD13: Car | AE13: 22.32 | AF13: 15.8 | AG13: 2.99
A14: 161 | B14: Car | C14: 30 | D14: =C14-C13 -> 1.8 | E14: 7.9 | F14: =D14*G14/3.6 -> 9.75 | G14: 19.5 | X14: =D15 -> 7.64 | Y14: =E15 -> 14.25 | Z14: =G15 -> 18.2 | AA14: =G14 -> 19.5 | AC14: 143 | AD14: Motorbike | AE14: 23.52 | AF14: 15.2 | AG14: 5
A15: 214 | B15: Car | C15: 37.64 | D15: =C15-C14 -> 7.64 | E15: 14.25 | F15: =D15*G15/3.6 -> 38.624444 | G15: 18.2 | J15: Time Mean Speed | X15: =D16 -> 4.2 | Y15: =E16 -> 18.38 | Z15: =G16 -> 12.6 | AA15: =G15 -> 18.2 | AC15: 130 | AD15: Car | AE15: 24.12 | AF15: 15.3 | AG15: 0.76999998
A16: 216 | B16: Car | C16: 41.84 | D16: =C16-C15 -> 4.2 | E16: 18.38 | F16: =D16*G16/3.6 -> 14.7 | G16: 12.6 | J16: Car | K16: =AVERAGEIFS($G$3:$G$30, $B$3:$B$30, J16, $G$3:$G$30, "<>0") -> 19.342857 | X16: =D17 -> 1.28 | Y16: =E17 -> 2.87 | Z16: =G17 -> 22.6 | AA16: =G16 -> 12.6 | AC16: 138 | AD16: Truck | AE16: 25.52 | AF16: 15 | AG16: 6.4200001
A17: 258 | B17: Car | C17: 43.12 | D17: =C17-C16 -> 1.28 | E17: 2.87 | F17: =D17*G17/3.6 -> 8.0355556 | G17: 22.6 | J17: Motorbike | K17: =AVERAGEIFS($G$3:$G$30, $B$3:$B$30, J17, $G$3:$G$30, "<>0") -> 21.7 | X17: =D18 -> 2 | Y17: =E18 -> 11.64 | Z17: =G18 -> 25.2 | AA17: =G17 -> 22.6 | AC17: 147 | AD17: Motorbike | AE17: 25.72 | AF17: 20.5 | AG17: -0.77999997
A18: 260 | B18: Car | C18: 45.12 | D18: =C18-C17 -> 2 | E18: 11.64 | F18: =D18*G18/3.6 -> 14 | G18: 25.2 | J18: CNG | K18: =AVERAGEIFS($G$3:$G$30, $B$3:$B$30, J18, $G$3:$G$30, "<>0") -> 14.3 | X18: =D19 -> 0 | Y18: =E19 -> 0 | Z18: =G19 -> 0 | AA18: =G18 -> 25.2
X19: =D20 -> 0 | Y19: =E20 -> 0 | Z19: =G20 -> 0 | AA19: =G19 -> 0 | AC19: 180 | AD19: CNG | AE19: 27.2 | AF19: 17.5 | AG19: -5.6999998
X20: =D21 -> 0 | Y20: =E21 -> 0 | Z20: =G21 -> 0 | AA20: =G20 -> 0 | AC20: 156 | AD20: CNG | AE20: 28.44 | AF20: 16.799999 | AG20: 3.4200001
X21: =D22 -> 0 | Y21: =E22 -> 0 | Z21: =G22 -> 0 | AA21: =G21 -> 0 | AC21: 196 | AD21: Motorbike | AE21: 28.44 | AF21: 7.4000001 | AG21: 2.5699999
X22: =D23 -> 0 | Y22: =E23 -> 0 | Z22: =G23 -> 0 | AA22: =G22 -> 0 | AC22: 169 | AD22: Bus | AE22: 30.64 | AF22: 19.5 | AG22: -1.16
X23: =D24 -> 0 | Y23: =E24 -> 0 | Z23: =G24 -> 0 | AA23: =G23 -> 0 | AC23: 204 | AD23: Motorbike | AE23: 30.8 | AF23: 19.9 | AG23: 10.45
X24: =D25 -> 0 | Y24: =E25 -> 0 | Z24: =G25 -> 0 | AA24: =G24 -> 0
X25: =D26 -> 0 | Y25: =E26 -> 0 | Z25: =G26 -> 0 | AA25: =G25 -> 0 | AC25: 208 | AD25: Motorbike | AE25: 31.32 | AF25: 21.799999 | AG25: 7.4400001
X26: =D27 -> 0 | Y26: =E27 -> 0 | Z26: =G27 -> 0 | AA26: =G26 -> 0 | AC26: 226 | AD26: Car | AE26: 32.72 | AF26: 0 | AG26: 5.4099998
X27: =D28 -> 0 | Y27: =E28 -> 0 | Z27: =G28 -> 0 | AA27: =G27 -> 0 | AC27: 170 | AD27: Truck | AE27: 33.6 | AF27: 8.6999998 | AG27: 4.8299999
AC29: 237 | AD29: Car | AE29: 35.4 | AF29: 18 | AG29: -8.79
AC30: 250 | AD30: Motorbike | AE30: 35.52 | AF30: 0 | AG30: 9.3900003
AC31: 218 | AD31: Car | AE31: 37.32 | AF31: 20.200001 | AG31: -9.1400003
AC32: 255 | AD32: Motorbike | AE32: 38.6 | AF32: 22.4 | AG32: 5.3499999
A33: Lane 3 | J33: Headway | K33: Gap (m) | AC33: 285 | AD33: Motorbike | AE33: 39.64 | AF33: 0 | AG33: 13.75
A34: L3_ID | B34: L3_Cls | C34: L3_Time | D34: Headway | E34: L3_Gap | F34: Gap (Calc) | G34: L3_Speed | J34: 0 | K34: 0 | AC34: 236 | AD34: Car | AE34: 40.92 | AF34: 22.6 | AG34: -9.6800003
A35: 22 | B35: CNG | C35: 7.72 | D35: 0 | F35: 0 | G35: 15.5 | J35: 0.2 | K35: =SLOPE($E$35:$E$58, $D$35:$D$58) * J35 + INTERCEPT($E$35:$E$58, $D$35:$D$58) -> 4.173835 | AC35: 246 | AD35: Car | AE35: 42.44 | AF35: 26.4 | AG35: 10.02
A36: 9 | B36: CNG | C36: 9.84 | D36: =C36-C35 -> 2.12 | E36: 10.07 | F36: =D36*G36/3.6 -> 10.541111 | G36: 17.9 | J36: 0.4 | K36: =SLOPE($E$35:$E$58, $D$35:$D$58) * J36 + INTERCEPT($E$35:$E$58, $D$35:$D$58) -> 4.5715767
A37: 46 | B37: Car | C37: 11.04 | D37: =C37-C36 -> 1.2 | E37: 5.64 | F37: =D37*G37/3.6 -> 6.5 | G37: 19.5 | J37: 0.6 | K37: =SLOPE($E$35:$E$58, $D$35:$D$58) * J37 + INTERCEPT($E$35:$E$58, $D$35:$D$58) -> 4.9693184
A38: 56 | B38: CNG | C38: 12.72 | D38: =C38-C37 -> 1.68 | E38: 9.01 | F38: =D38*G38/3.6 -> 11.013333 | G38: 23.6 | J38: 0.8 | K38: =SLOPE($E$35:$E$58, $D$35:$D$58) * J38 + INTERCEPT($E$35:$E$58, $D$35:$D$58) -> 5.3670601
A39: 73 | B39: Motorbike | C39: 13.4 | D39: =C39-C38 -> 0.68 | E39: 4.33 | F39: =D39*G39/3.6 -> 3.5888889 | G39: 19 | J39: 1 | K39: =SLOPE($E$35:$E$58, $D$35:$D$58) * J39 + INTERCEPT($E$35:$E$58, $D$35:$D$58) -> 5.7648018
A40: 10 | B40: Car | C40: 15.24 | D40: =C40-C39 -> 1.84 | E40: 7.09 | F40: =D40*G40/3.6 -> 8.0755556 | G40: 15.8 | J40: 1.2 | K40: =SLOPE($E$35:$E$58, $D$35:$D$58) * J40 + INTERCEPT($E$35:$E$58, $D$35:$D$58) -> 6.1625435
A41: 84 | B41: CNG | C41: 16 | D41: =C41-C40 -> 0.76 | E41: 7.4 | F41: =D41*G41/3.6 -> 4.8555556 | G41: 23 | J41: 1.4 | K41: =SLOPE($E$35:$E$58, $D$35:$D$58) * J41 + INTERCEPT($E$35:$E$58, $D$35:$D$58) -> 6.5602852
...

Sheet 3.40
A1: Lane 2 | X1: Headway | Z1: Speed
A2: L2_ID | B2: L2_Cls | C2: L2_Time | D2: Headway | E2: L2_Gap | F2: Gap (Calc) | G2: L2_Speed | J2: Headway | K2: Gap (m) | X2: Time | Y2: Gap | Z2: Leader | AA2: Follower
A3: 6 | B3: Car | C3: 0.48 | D3: 0 | E3: 0 | F3: 0 | G3: 0 | J3: 0 | K3: 0 | X3: =D4 -> 1.64 | Y3: =E4 -> 12.43 | Z3: =G4 -> 25 | AA3: =G3 -> 0
A4: 2 | B4: Car | C4: 2.12 | D4: =C4-C3 -> 1.64 | E4: 12.43 | F4: =D4*G4/3.6 -> 11.388889 | G4: 25 | J4: 0.2 | K4: =SLOPE($E$3:$E$8, $D$3:$D$8) * J4 + INTERCEPT($E$3:$E$8, $D$3:$D$8) -> 0.48871526 | X4: =D5 -> 2.28 | Y4: =E5 -> 17.41 | Z4: =G5 -> 23.1 | AA4: =G4 -> 25
A5: 12 | B5: Car | C5: 4.4 | D5: =C5-C4 -> 2.28 | E5: 17.41 | F5: =D5*G5/3.6 -> 14.63 | G5: 23.1 | J5: 0.4 | K5: =SLOPE($E$3:$E$8, $D$3:$D$8) * J5 + INTERCEPT($E$3:$E$8, $D$3:$D$8) -> 2.0484155 | X5: =D6 -> 2.28 | Y5: =E6 -> 15.62 | Z5: =G6 -> 30 | AA5: =G5 -> 23.1
A6: 51 | B6: Motorbike | C6: 6.68 | D6: =C6-C5 -> 2.28 | E6: 15.62 | F6: =D6*G6/3.6 -> 19 | G6: 30 | J6: 0.6 | K6: =SLOPE($E$3:$E$8, $D$3:$D$8) * J6 + INTERCEPT($E$3:$E$8, $D$3:$D$8) -> 3.6081157 | X6: =D7 -> 2.12 | Y6: =E7 -> 16.64 | Z6: =G7 -> 21.8 | AA6: =G6 -> 30
A7: 63 | B7: CNG | C7: 8.8 | D7: =C7-C6 -> 2.12 | E7: 16.64 | F7: =D7*G7/3.6 -> 12.837778 | G7: 21.8 | J7: 0.8 | K7: =SLOPE($E$3:$E$8, $D$3:$D$8) * J7 + INTERCEPT($E$3:$E$8, $D$3:$D$8) -> 5.1678159 | X7: =D8 -> 1.08 | Y7: =E8 -> 4.78 | Z7: =G8 -> 21.5 | AA7: =G7 -> 21.8
A8: 42 | B8: Car | C8: 9.88 | D8: =C8-C7 -> 1.08 | E8: 4.78 | F8: =D8*G8/3.6 -> 6.45 | G8: 21.5 | J8: 1 | K8: =SLOPE($E$3:$E$8, $D$3:$D$8) * J8 + INTERCEPT($E$3:$E$8, $D$3:$D$8) -> 6.7275161 | X8: =D9 -> 0 | Y8: =E9 -> 0 | Z8: =G9 -> 0 | AA8: =G8 -> 21.5
J9: 1.2 | K9: =SLOPE($E$3:$E$8, $D$3:$D$8) * J9 + INTERCEPT($E$3:$E$8, $D$3:$D$8) -> 8.2872163 | X9: =D10 -> 0 | Y9: =E10 -> 0 | Z9: =G10 -> 11.7 | AA9: =G9 -> 0
A10: 73 | B10: Car | C10: 12.48 | E10: 0 | F10: 0 | G10: 11.7 | J10: 1.4 | K10: =SLOPE($E$3:$E$8, $D$3:$D$8) * J10 + INTERCEPT($E$3:$E$8, $D$3:$D$8) -> 9.8469165 | X10: =D11 -> 4.4 | Y10: =E11 -> 16.91 | Z10: =G11 -> 21.7 | AA10: =G10 -> 11.7
A11: 81 | B11: Motorbike | C11: 16.88 | D11: =C11-C10 -> 4.4 | E11: 16.91 | F11: =D11*G11/3.6 -> 26.522222 | G11: 21.7 | J11: 1.6 | K11: =SLOPE($E$3:$E$8, $D$3:$D$8) * J11 + INTERCEPT($E$3:$E$8, $D$3:$D$8) -> 11.406617 | X11: =D12 -> 1.6 | Y11: =E12 -> 10.14 | Z11: =G12 -> 24.3 | AA11: =G11 -> 21.7
A12: 100 | B12: Car | C12: 18.48 | D12: =C12-C11 -> 1.6 | E12: 10.14 | F12: =D12*G12/3.6 -> 10.8 | G12: 24.3 | J12: 1.8 | K12: =SLOPE($E$3:$E$8, $D$3:$D$8) * J12 + INTERCEPT($E$3:$E$8, $D$3:$D$8) -> 12.966317 | X12: =D13 -> 2.92 | Y12: =E13 -> 15.63 | Z12: =G13 -> 21.3 | AA12: =G12 -> 24.3
A13: 121 | B13: Car | C13: 21.4 | D13: =C13-C12 -> 2.92 | E13: 15.63 | F13: =D13*G13/3.6 -> 17.276667 | G13: 21.3 | J13: 2 | K13: =SLOPE($E$3:$E$8, $D$3:$D$8) * J13 + INTERCEPT($E$3:$E$8, $D$3:$D$8) -> 14.526017 | X13: =D14 -> 0.88 | Y13: =E14 -> 7.32 | Z13: =G14 -> 23.5 | AA13: =G13 -> 21.3
A14: 119 | B14: Car | C14: 22.28 | D14: =C14-C13 -> 0.88 | E14: 7.32 | F14: =D14*G14/3.6 -> 5.7444444 | G14: 23.5 | X14: =D15 -> 2.12 | Y14: =E15 -> 11.78 | Z14: =G15 -> 22.1 | AA14: =G14 -> 23.5
A15: 134 | B15: Car | C15: 24.4 | D15: =C15-C14 -> 2.12 | E15: 11.78 | F15: =D15*G15/3.6 -> 13.014444 | G15: 22.1 | J15: Time Mean Speed | X15: =D16 -> 1.68 | Y15: =E16 -> 10.04 | Z15: =G16 -> 22.2 | AA15: =G15 -> 22.1
A16: 136 | B16: Car | C16: 26.08 | D16: =C16-C15 -> 1.68 | E16: 10.04 | F16: =D16*G16/3.6 -> 10.36 | G16: 22.2 | J16: Car | K16: =AVERAGEIFS($G$3:$G$30, $B$3:$B$30, J16, $G$3:$G$30, "<>0") -> 21.55 | X16: =D17 -> 0.44 | Y16: =E17 -> 2.44 | Z16: =G17 -> 20.4 | AA16: =G16 -> 22.2
A17: 138 | B17: Car | C17: 26.52 | D17: =C17-C16 -> 0.44 | E17: 2.44 | F17: =D17*G17/3.6 -> 2.4933333 | G17: 20.4 | J17: Motorbike | K17: =AVERAGEIFS($G$3:$G$30, $B$3:$B$30, J17, $G$3:$G$30, "<>0") -> 25.933333 | X17: =D18 -> 1 | Y17: =E18 -> 5.03 | Z17: =G18 -> 24.9 | AA17: =G17 -> 20.4
A18: 150 | B18: Car | C18: 27.52 | D18: =C18-C17 -> 1 | E18: 5.03 | F18: =D18*G18/3.6 -> 6.9166667 | G18: 24.9 | J18: CNG | K18: =AVERAGEIFS($G$3:$G$30, $B$3:$B$30, J18, $G$3:$G$30, "<>0") -> 21.8 | X18: =D19 -> 1.56 | Y18: =E19 -> 9.85 | Z18: =G19 -> 26.1 | AA18: =G18 -> 24.9
A19: 163 | B19: Motorbike | C19: 29.08 | D19: =C19-C18 -> 1.56 | E19: 9.85 | F19: =D19*G19/3.6 -> 11.31 | G19: 26.1 | X19: =D20 -> 4.92 | Y19: =E20 -> 15.16 | Z19: =G20 -> 18.6 | AA19: =G19 -> 26.1
A20: 179 | B20: Car | C20: 34 | D20: =C20-C19 -> 4.92 | E20: 15.16 | F20: =D20*G20/3.6 -> 25.42 | G20: 18.6 | X20: =D21 -> 0 | Y20: =E21 -> 0 | Z20: =G21 -> 0 | AA20: =G20 -> 18.6
X21: =D22 -> 0 | Y21: =E22 -> 0 | Z21: =G22 -> 0 | AA21: =G21 -> 0
X22: =D23 -> 0 | Y22: =E23 -> 0 | Z22: =G23 -> 0 | AA22: =G22 -> 0
X23: =D24 -> 0 | Y23: =E24 -> 0 | Z23: =G24 -> 0 | AA23: =G23 -> 0
X24: =D25 -> 0 | Y24: =E25 -> 0 | Z24: =G25 -> 0 | AA24: =G24 -> 0
X25: =D26 -> 0 | Y25: =E26 -> 0 | Z25: =G26 -> 0 | AA25: =G25 -> 0
X26: =D27 -> 0 | Y26: =E27 -> 0 | Z26: =G27 -> 0 | AA26: =G26 -> 0
X27: =D28 -> 0 | Y27: =E28 -> 0 | Z27: =G28 -> 0 | AA27: =G27 -> 0
A33: Lane 3 | J33: Headway | K33: Gap (m)
A34: L3_ID | B34: L3_Cls | C34: L3_Time | D34: Headway | E34: L3_Gap | F34: Gap (Calc) | G34: L3_Speed | J34: 0 | K34: 0
A35: 3 | B35: CNG | C35: 0.4 | D35: 0 | E35: 0 | F35: 0 | G35: 0 | J35: 0.2 | K35: =SLOPE($E$35:$E$58, $D$35:$D$58) * J35 + INTERCEPT($E$35:$E$58, $D$35:$D$58) -> 4.2597382
A36: 10 | B36: CNG | C36: 1.48 | D36: =C36-C35 -> 1.08 | E36: 7.15 | F36: =D36*G36/3.6 -> 4.29 | G36: 14.3 | J36: 0.4 | K36: =SLOPE($E$35:$E$58, $D$35:$D$58) * J36 + INTERCEPT($E$35:$E$58, $D$35:$D$58) -> 4.6894061
A37: 11 | B37: CNG | C37: 2.92 | D37: =C37-C36 -> 1.44 | E37: 10.57 | F37: =D37*G37/3.6 -> 7.72 | G37: 19.3 | J37: 0.6 | K37: =SLOPE($E$35:$E$58, $D$35:$D$58) * J37 + INTERCEPT($E$35:$E$58, $D$35:$D$58) -> 5.119074
A38: 41 | B38: Motorbike | C38: 4.68 | D38: =C38-C37 -> 1.76 | E38: 10.93 | F38: =D38*G38/3.6 -> 8.2622222 | G38: 16.9 | J38: 0.8 | K38: =SLOPE($E$35:$E$58, $D$35:$D$58) * J38 + INTERCEPT($E$35:$E$58, $D$35:$D$58) -> 5.548742
A39: 16 | B39: CNG | C39: 5.12 | D39: =C39-C38 -> 0.44 | E39: 1.91 | F39: =D39*G39/3.6 -> 2.3711111 | G39: 19.4 | J39: 1 | K39: =SLOPE($E$35:$E$58, $D$35:$D$58) * J39 + INTERCEPT($E$35:$E$58, $D$35:$D$58) -> 5.9784099
A40: 57 | B40: Motorbike | C40: 6.48 | D40: =C40-C39 -> 1.36 | E40: 7.7 | F40: =D40*G40/3.6 -> 9.18 | G40: 24.3 | J40: 1.2 | K40: =SLOPE($E$35:$E$58, $D$35:$D$58) * J40 + INTERCEPT($E$35:$E$58, $D$35:$D$58) -> 6.4080778
A41: 63 | B41: CNG | C41: 9.08 | D41: =C41-C40 -> 2.6 | E41: 9.27 | F41: =D41*G41/3.6 -> 15.238889 | G41: 21.1 | J41: 1.4 | K41: =SLOPE($E$35:$E$58, $D$35:$D$58) * J41 + INTERCEPT($E$35:$E$58, $D$35:$D$58) -> 6.8377457
A42: 46 | B42: Car | C42: 10.48 | D42: =C42-C41 -> 1.4 | E42: 10.56 | F42: =D42*G42/3.6 -> 10.15 | G42: 26.1 | J42: 1.6 | K42: =SLOPE($E$35:$E$58, $D$35:$D$58) * J42 + INTERCEPT($E$35:$E$58, $D$35:$D$58) -> 7.2674137
A43: 107 | B43: Motorbike | C43: 17.48 | D43: =C43-C42 -> 7 | E43: 14.54 | F43: =D43*G43/3.6 -> 39.472222 | G43: 20.3 | J43: 1.8 | K43: =SLOPE($E$35:$E$58, $D$35:$D$58) * J43 + INTERCEPT($E$35:$E$58, $D$35:$D$58) -> 7.6970816
A44: 103 | B44: Motorbike | C44: 18.28 | D44: =C44-C43 -> 0.8 | E44: 4.7 | F44: =D44*G44/3.6 -> 3.7555556 | G44: 16.9 | J44: 2 | K44: =SLOPE($E$35:$E$58, $D$35:$D$58) * J44 + INTERCEPT($E$35:$E$58, $D$35:$D$58) -> 8.1267495
A45: 97 | B45: Car | C45: 19.52 | D45: =C45-C44 -> 1.24 | E45: 5.1 | F45: =D45*G45/3.6 -> 6.7511111 | G45: 19.6
...

Sheet 8.15
A1: Lane 2 | X1: Headway | Z1: Speed | AB1: Vehicle Type
A2: L2_ID | B2: L2_Cls | C2: L2_Time | D2: Headway | E2: L2_Gap | F2: Gap (Calc) | G2: L2_Speed | J2: Headway | K2: Gap (m) | X2: Time | Y2: Gap | Z2: Leader | AA2: Follower | AB2: Leader | AC2: Follower
A3: 2 | B3: Car | C3: 2.52 | D3: 0 | E3: 0 | F3: 0 | G3: 18.4 | J3: 0 | K3: 0 | X3: =D4 -> 1.96 | Y3: =E4 -> 11.34 | Z3: =G4 -> 23.6 | AA3: =G3 -> 18.4 | AB3: Car | AC3: Car
A4: 4 | B4: Car | C4: 4.48 | D4: =C4-C3 -> 1.96 | E4: 11.34 | F4: =D4*G4/3.6 -> 12.848889 | G4: 23.6 | J4: 0.2 | K4: =SLOPE($E$3:$E$27, $D$3:$D$27) * J4 + INTERCEPT($E$3:$E$27, $D$3:$D$27) -> 5.0572626 | X4: =D5 -> 0.6 | Y4: =E5 -> 4.52 | Z4: =G5 -> 16.1 | AA4: =G4 -> 23.6 | AB4: Car | AC4: Car
A5: 6 | B5: Car | C5: 5.08 | D5: =C5-C4 -> 0.6 | E5: 4.52 | F5: =D5*G5/3.6 -> 2.6833333 | G5: 16.1 | J5: 0.4 | K5: =SLOPE($E$3:$E$27, $D$3:$D$27) * J5 + INTERCEPT($E$3:$E$27, $D$3:$D$27) -> 5.6477252 | X5: =D6 -> 0.92 | Y5: =E6 -> 1.5 | Z5: =G6 -> 31.3 | AA5: =G5 -> 16.1 | AB5: Car | AC5: Car
A6: 15 | B6: Car | C6: 6 | D6: =C6-C5 -> 0.92 | E6: 1.5 | F6: =D6*G6/3.6 -> 7.9988889 | G6: 31.3 | J6: 0.6 | K6: =SLOPE($E$3:$E$27, $D$3:$D$27) * J6 + INTERCEPT($E$3:$E$27, $D$3:$D$27) -> 6.2381877 | X6: =D7 -> 1.08 | Y6: =E7 -> 9.11 | Z6: =G7 -> 19.8 | AA6: =G6 -> 31.3
A7: 23 | B7: Car | C7: 7.08 | D7: =C7-C6 -> 1.08 | E7: 9.11 | F7: =D7*G7/3.6 -> 5.94 | G7: 19.8 | J7: 0.8 | K7: =SLOPE($E$3:$E$27, $D$3:$D$27) * J7 + INTERCEPT($E$3:$E$27, $D$3:$D$27) -> 6.8286503 | X7: =D8 -> 1.84 | Y7: =E8 -> 9.32 | Z7: =G8 -> 17.1 | AA7: =G7 -> 19.8
A8: 56 | B8: CNG | C8: 8.92 | D8: =C8-C7 -> 1.84 | E8: 9.32 | F8: =D8*G8/3.6 -> 8.74 | G8: 17.1 | J8: 1 | K8: =SLOPE($E$3:$E$27, $D$3:$D$27) * J8 + INTERCEPT($E$3:$E$27, $D$3:$D$27) -> 7.4191129 | X8: =D9 -> 2.56 | Y8: =E9 -> 14.78 | Z8: =G9 -> 26.6 | AA8: =G8 -> 17.1
A9: 80 | B9: Motorbike | C9: 11.48 | D9: =C9-C8 -> 2.56 | E9: 14.78 | F9: =D9*G9/3.6 -> 18.915556 | G9: 26.6 | J9: 1.2 | K9: =SLOPE($E$3:$E$27, $D$3:$D$27) * J9 + INTERCEPT($E$3:$E$27, $D$3:$D$27) -> 8.0095755 | X9: =D10 -> 6.12 | Y9: =E10 -> 15.51 | Z9: =G10 -> 24.4 | AA9: =G9 -> 26.6
A10: 116 | B10: Car | C10: 17.6 | D10: =C10-C9 -> 6.12 | E10: 15.51 | F10: =D10*G10/3.6 -> 41.48 | G10: 24.4 | J10: 1.4 | K10: =SLOPE($E$3:$E$27, $D$3:$D$27) * J10 + INTERCEPT($E$3:$E$27, $D$3:$D$27) -> 8.6000381 | X10: =D11 -> 1.88 | Y10: =E11 -> 11.21 | Z10: =G11 -> 25.4 | AA10: =G10 -> 24.4
A11: 90 | B11: Car | C11: 19.48 | D11: =C11-C10 -> 1.88 | E11: 11.21 | F11: =D11*G11/3.6 -> 13.264444 | G11: 25.4 | J11: 1.6 | K11: =SLOPE($E$3:$E$27, $D$3:$D$27) * J11 + INTERCEPT($E$3:$E$27, $D$3:$D$27) -> 9.1905007 | X11: =D12 -> 3.12 | Y11: =E12 -> 16.72 | Z11: =G12 -> 22.7 | AA11: =G11 -> 25.4
A12: 137 | B12: Car | C12: 22.6 | D12: =C12-C11 -> 3.12 | E12: 16.72 | F12: =D12*G12/3.6 -> 19.673333 | G12: 22.7 | J12: 1.8 | K12: =SLOPE($E$3:$E$27, $D$3:$D$27) * J12 + INTERCEPT($E$3:$E$27, $D$3:$D$27) -> 9.7809633 | X12: =D13 -> 0.72 | Y12: =E13 -> 5.43 | Z12: =G13 -> 23.9 | AA12: =G12 -> 22.7
A13: 119 | B13: CNG | C13: 23.32 | D13: =C13-C12 -> 0.72 | E13: 5.43 | F13: =D13*G13/3.6 -> 4.78 | G13: 23.9 | J13: 2 | K13: =SLOPE($E$3:$E$27, $D$3:$D$27) * J13 + INTERCEPT($E$3:$E$27, $D$3:$D$27) -> 10.371426 | X13: =D14 -> 1.48 | Y13: =E14 -> 7.01 | Z13: =G14 -> 24.1 | AA13: =G13 -> 23.9
A14: 149 | B14: Car | C14: 24.8 | D14: =C14-C13 -> 1.48 | E14: 7.01 | F14: =D14*G14/3.6 -> 9.9077778 | G14: 24.1 | X14: =D15 -> 2.32 | Y14: =E15 -> 16.59 | Z14: =G15 -> 29.5 | AA14: =G14 -> 24.1
A15: 165 | B15: Car | C15: 27.12 | D15: =C15-C14 -> 2.32 | E15: 16.59 | F15: =D15*G15/3.6 -> 19.011111 | G15: 29.5 | J15: Time Mean Speed | X15: =D16 -> 2.76 | Y15: =E16 -> 17.5 | Z15: =G16 -> 28.2 | AA15: =G15 -> 29.5
A16: 177 | B16: Car | C16: 29.88 | D16: =C16-C15 -> 2.76 | E16: 17.5 | F16: =D16*G16/3.6 -> 21.62 | G16: 28.2 | J16: Car | K16: =AVERAGEIFS($G$3:$G$30, $B$3:$B$30, J16, $G$3:$G$30, "<>0") -> 24.133333 | X16: =D17 -> 2.04 | Y16: =E17 -> 13.26 | Z16: =G17 -> 26.1 | AA16: =G16 -> 28.2
A17: 188 | B17: Car | C17: 31.92 | D17: =C17-C16 -> 2.04 | E17: 13.26 | F17: =D17*G17/3.6 -> 14.79 | G17: 26.1 | J17: Motorbike | K17: =AVERAGEIFS($G$3:$G$30, $B$3:$B$30, J17, $G$3:$G$30, "<>0") -> 26.6 | X17: =D18 -> 0 | Y17: =E18 -> 0 | Z17: =G18 -> 0 | AA17: =G17 -> 26.1
J18: CNG | K18: =AVERAGEIFS($G$3:$G$30, $B$3:$B$30, J18, $G$3:$G$30, "<>0") -> 20.5 | X18: =D19 -> 0 | Y18: =E19 -> 0 | Z18: =G19 -> 0 | AA18: =G18 -> 0
X19: =D20 -> 0 | Y19: =E20 -> 0 | Z19: =G20 -> 0 | AA19: =G19 -> 0
X20: =D21 -> 0 | Y20: =E21 -> 0 | Z20: =G21 -> 0 | AA20: =G20 -> 0
X21: =D22 -> 0 | Y21: =E22 -> 0 | Z21: =G22 -> 0 | AA21: =G21 -> 0
X22: =D23 -> 0 | Y22: =E23 -> 0 | Z22: =G23 -> 0 | AA22: =G22 -> 0
X23: =D24 -> 0 | Y23: =E24 -> 0 | Z23: =G24 -> 0 | AA23: =G23 -> 0
X24: =D25 -> 0 | Y24: =E25 -> 0 | Z24: =G25 -> 0 | AA24: =G24 -> 0
X25: =D26 -> 0 | Y25: =E26 -> 0 | Z25: =G26 -> 0 | AA25: =G25 -> 0
X26: =D27 -> 0 | Y26: =E27 -> 0 | Z26: =G27 -> 0 | AA26: =G26 -> 0
X27: =D28 -> 0 | Y27: =E28 -> 0 | Z27: =G28 -> 0 | AA27: =G27 -> 0
AB31: Normalizing Gap by speed | AD31: Gap
Y32: Gap/V | Z32: Headway | AB32: Headway | AC32: Gap/V | AD32: 15 | AE32: 18 | AF32: 20 | AG32: 25
A33: Lane 3 | J33: Headway | K33: Gap (m) | Y33: 0 | Z33: 0 | AB33: 0 | AC33: 0 | AD33: 0 | AE33: 0 | AF33: 0 | AG33: 0
A34: L3_ID | B34: L3_Cls | C34: L3_Time | D34: Headway | E34: L3_Gap | F34: Gap (Calc) | G34: L3_Speed | J34: 0 | K34: 0 | Y34: =E4/G4 -> 0.48050847 | Z34: 0.4 | AB34: 0.2 | AC34: =SLOPE($Y$33:$Y$57, $Z$33:$Z$57) * AB34 + INTERCEPT($Y$33:$Y$57, $Z$33:$Z$57) -> #DIV/0! | AD34: =$AD$32*AC34 -> #DIV/0! | AE34: =$AE$32*AC34 -> #DIV/0! | AF34: =$AF$32*AC34 -> #DIV/0! | AG34: =$AG$32*AC34 -> #DIV/0!
A35: 12 | B35: Motorbike | C35: 1 | D35: 0 | E35: 0 | F35: 0 | G35: 16.799999 | J35: 0.2 | K35: =SLOPE($E$35:$E$58, $D$35:$D$58) * J35 + INTERCEPT($E$35:$E$58, $D$35:$D$58) -> 1.7938653 | Y35: =E5/G5 -> 0.28074534 | Z35: 1.04 | AB35: 0.4 | AC35: =SLOPE($Y$33:$Y$57, $Z$33:$Z$57) * AB35 + INTERCEPT($Y$33:$Y$57, $Z$33:$Z$57) -> #DIV/0! | AD35: =$AD$32*AC35 -> #DIV/0! | AE35: =$AE$32*AC35 -> #DIV/0! | AF35: =$AF$32*AC35 -> #DIV/0! | AG35: =$AG$32*AC35 -> #DIV/0!
A36: 3 | B36: CNG | C36: 2.2 | D36: =C36-C35 -> 1.2 | E36: 5.9699998 | F36: =D36*G36/3.6 -> 7.0666669 | G36: 21.200001 | J36: 0.4 | K36: =SLOPE($E$35:$E$58, $D$35:$D$58) * J36 + INTERCEPT($E$35:$E$58, $D$35:$D$58) -> 2.6639211 | Y36: =E6/G6 -> 0.047923323 | Z36: 1.16 | AB36: 0.6 | AC36: =SLOPE($Y$33:$Y$57, $Z$33:$Z$57) * AB36 + INTERCEPT($Y$33:$Y$57, $Z$33:$Z$57) -> #DIV/0! | AD36: =$AD$32*AC36 -> #DIV/0! | AE36: =$AE$32*AC36 -> #DIV/0! | AF36: =$AF$32*AC36 -> #DIV/0! | AG36: =$AG$32*AC36 -> #DIV/0!
A37: 5 | B37: CNG | C37: 3.52 | D37: =C37-C36 -> 1.32 | E37: 8.9899998 | F37: =D37*G37/3.6 -> 7.5533335 | G37: 20.6 | J37: 0.6 | K37: =SLOPE($E$35:$E$58, $D$35:$D$58) * J37 + INTERCEPT($E$35:$E$58, $D$35:$D$58) -> 3.5339768 | Y37: =E7/G7 -> 0.46010101 | Z37: 1.24 | AB37: 0.8 | AC37: =SLOPE($Y$33:$Y$57, $Z$33:$Z$57) * AB37 + INTERCEPT($Y$33:$Y$57, $Z$33:$Z$57) -> #DIV/0! | AD37: =$AD$32*AC37 -> #DIV/0! | AE37: =$AE$32*AC37 -> #DIV/0! | AF37: =$AF$32*AC37 -> #DIV/0! | AG37: =$AG$32*AC37 -> #DIV/0!
A38: 13 | B38: Car | C38: 4.92 | D38: =C38-C37 -> 1.4 | E38: 5.5700002 | F38: =D38*G38/3.6 -> 7.466667 | G38: 19.200001 | J38: 0.8 | K38: =SLOPE($E$35:$E$58, $D$35:$D$58) * J38 + INTERCEPT($E$35:$E$58, $D$35:$D$58) -> 4.4040326 | Y38: =E8/G8 -> 0.54502924 | Z38: 2.16 | AB38: 1 | AC38: =SLOPE($Y$33:$Y$57, $Z$33:$Z$57) * AB38 + INTERCEPT($Y$33:$Y$57, $Z$33:$Z$57) -> #DIV/0! | AD38: =$AD$32*AC38 -> #DIV/0! | AE38: =$AE$32*AC38 -> #DIV/0! | AF38: =$AF$32*AC38 -> #DIV/0! | AG38: =$AG$32*AC38 -> #DIV/0!
A39: 58 | B39: Motorbike | C39: 5.72 | D39: =C39-C38 -> 0.8 | E39: 4.7399998 | F39: =D39*G39/3.6 -> 0 | G39: 0 | J39: 1 | K39: =SLOPE($E$35:$E$58, $D$35:$D$58) * J39 + INTERCEPT($E$35:$E$58, $D$35:$D$58) -> 5.2740883 | Y39: =E9/G9 -> 0.5556391 | Z39: 2.64 | AB39: 1.2 | AC39: =SLOPE($Y$33:$Y$57, $Z$33:$Z$57) * AB39 + INTERCEPT($Y$33:$Y$57, $Z$33:$Z$57) -> #DIV/0! | AD39: =$AD$32*AC39 -> #DIV/0! | AE39: =$AE$32*AC39 -> #DIV/0! | AF39: =$AF$32*AC39 -> #DIV/0! | AG39: =$AG$32*AC39 -> #DIV/0!
A40: 21 | B40: CNG | C40: 6.8 | D40: =C40-C39 -> 1.08 | E40: 10.04 | F40: =D40*G40/3.6 -> 6.8699999 | G40: 22.9 | J40: 1.2 | K40: =SLOPE($E$35:$E$58, $D$35:$D$58) * J40 + INTERCEPT($E$35:$E$58, $D$35:$D$58) -> 6.1441441 | Y40: =E10/G10 -> 0.63565574 | Z40: 2.2 | AB40: 1.4 | AC40: =SLOPE($Y$33:$Y$57, $Z$33:$Z$57) * AB40 + INTERCEPT($Y$33:$Y$57, $Z$33:$Z$57) -> #DIV/0! | AD40: =$AD$32*AC40 -> #DIV/0! | AE40: =$AE$32*AC40 -> #DIV/0! | AF40: =$AF$32*AC40 -> #DIV/0! | AG40: =$AG$32*AC40 -> #DIV/0!
A41: 36 | B41: CNG | C41: 6.88 | D41: =C41-C40 -> 0.08 | E41: -1.05 | F41: =D41*G41/3.6 -> 0.41777776 | G41: 18.799999 | J41: 1.4 | K41: =SLOPE($E$35:$E$58, $D$35:$D$58) * J41 + INTERCEPT($E$35:$E$58, $D$35:$D$58) -> 7.0141998 | Y41: =E11/G11 -> 0.44133858 | Z41: 2.68 | AB41: 1.6 | AC41: =SLOPE($Y$33:$Y$57, $Z$33:$Z$57) * AB41 + INTERCEPT($Y$33:$Y$57, $Z$33:$Z$57) -> #DIV/0! | AD41: =$AD$32*AC41 -> #DIV/0! | AE41: =$AE$32*AC41 -> #DIV/0! | AF41: =$AF$32*AC41 -> #DIV/0! | AG41: =$AG$32*AC41 -> #DIV/0!
A42: 79 | B42: Motorbike | C42: 8.12 | D42: =C42-C41 -> 1.24 | E42: 5.6799998 | F42: =D42*G42/3.6 -> 0 | G42: 0 | J42: 1.6 | K42: =SLOPE($E$35:$E$58, $D$35:$D$58) * J42 + INTERCEPT($E$35:$E$58, $D$35:$D$58) -> 7.8842556 | Y42: =E12/G12 -> 0.73656388 | Z42: 1.48 | AB42: 1.8 | AC42: =SLOPE($Y$33:$Y$57, $Z$33:$Z$57) * AB42 + INTERCEPT($Y$33:$Y$57, $Z$33:$Z$57) -> #DIV/0! | AD42: =$AD$32*AC42 -> #DIV/0! | AE42: =$AE$32*AC42 -> #DIV/0! | AF42: =$AF$32*AC42 -> #DIV/0! | AG42: =$AG$32*AC42 -> #DIV/0!
A43: 20 | B43: Motorbike | C43: 8.6 | D43: =C43-C42 -> 0.48 | E43: -0.050000001 | F43: =D43*G43/3.6 -> 4.4799998 | G43: 33.599998 | J43: 1.8 | K43: =SLOPE($E$35:$E$58, $D$35:$D$58) * J43 + INTERCEPT($E$35:$E$58, $D$35:$D$58) -> 8.7543114 | Y43: =E13/G13 -> 0.22719665 | Z43: 1.64 | AB43: 2 | AC43: =SLOPE($Y$33:$Y$57, $Z$33:$Z$57) * AB43 + INTERCEPT($Y$33:$Y$57, $Z$33:$Z$57) -> #DIV/0! | AD43: =$AD$32*AC43 -> #DIV/0! | AE43: =$AE$32*AC43 -> #DIV/0! | AF43: =$AF$32*AC43 -> #DIV/0! | AG43: =$AG$32*AC43 -> #DIV/0!
...

Sheet 8.58
A1: Lane 2 | X1: Headway | Z1: Speed | AB1: Vehicle Type
A2: L2_ID | B2: L2_Cls | C2: L2_Time | D2: Headway | E2: L2_Gap | F2: Gap (Calc) | G2: L2_Speed | J2: Headway | K2: Gap (m) | X2: Time | Y2: Gap | Z2: Leader | AA2: Follower | AB2: Leader | AC2: Follower
A3: 2 | B3: Car | C3: 3.4 | D3: 0 | E3: 0 | F3: 0 | G3: 21.4 | J3: 0 | K3: 0 | X3: =D4 -> 2.88 | Y3: =E4 -> 16.64 | Z3: =G4 -> 19.1 | AA3: =G3 -> 21.4 | AB3: Car | AC3: Car
A4: 13 | B4: Car | C4: 6.28 | D4: =C4-C3 -> 2.88 | E4: 16.64 | F4: =D4*G4/3.6 -> 15.28 | G4: 19.1 | J4: 0.2 | K4: =SLOPE($E$3:$E$27, $D$3:$D$27) * J4 + INTERCEPT($E$3:$E$27, $D$3:$D$27) -> 1.9474919 | X4: =D5 -> 0.2 | Y4: =E5 -> 1.67 | Z4: =G5 -> 14.8 | AA4: =G4 -> 19.1 | AB4: Car | AC4: Car
